Workbook

Sheet machines assemblage
A1: Afkorting | B1: Machine | C1: Aantal | D1: opmerking
A2: L | B2: Leonard | C2: 1 | D2: rijst + pasta
A3: M | B3: Multifill | C3: 1 | D3: rijst + pasta
A4: K | B4: kaas strooier | C4: 1
A5: T | B5: Turbo | C5: x | D5: 8 enkele - 3 dubbele
A6: H | B6: Handtmann | C6: 5 | D6: 2 stroom verdeler
A7: I | B7: Multipond | C7: 1 | D7: L1 multiweger
B8: Isihda | C8: 1 | D8: L2 multiweger
A9: CFS | B9: CFS dieptrekker | C9: 1 | D9: L4
A10: G | B10: GROTE | C10: 2 | D10: Ham snijmachine
A13: 16 weegschalen

Sheet formaat delen mondini
A1: schaal | B1: kop | C1: bovenplaat | D1: opmerking
A2: UK59 | B2: 2 | C2: 2 bovenplaten | D2: Lijn 1 en lijn 2 tergelijkertijd mogelijk
A3: UK59kraft | B3: =UK59 | C3: 2 bovenplaten | D3: Lijn 1 en lijn 2 tergelijkertijd mogelijk
A4: UK57 | B4: =UK59 | C4: 1 bovenplaat | D4: Lijn 1 OF lijn 2
A5: OB36 | B5: =UK59 | C5: 1 bovenplaat | D5: Lijn 1 OF lijn 2
A6: C2187 | B6: =UK59 | C6: 2 bovenplaten | D6: Lijn 1 en lijn 2 tergelijkertijd mogelijk
A7: Novato | B7: =UK59 | C7: 2 bovenplaat | D7: Lijn 1 en lijn 2 tergelijkertijd mogelijk
A8: C2325 | B8: 1 | C8: 1 bovenplaat | D8: moet op lijn 2
A9: C2227 | B9: 2 | C9: 2 bovenplaten | D9: Lijn 1 en lijn 2 tergelijkertijd mogelijk
A10: AR-1150 | B10: =C2227 | C10: 1 bovenplaat | D10: Lijn 1 OF lijn 2
A11: C2208 | B11: 1 | C11: 1 bovenplaat | D11: Lijn 1 OF lijn 2
A12: C2176 | B12: 1 | C12: 1 bovenplaat | D12: Lijn 1 OF lijn 2
A13: kraft rond | B13: 1 | C13: 1 | D13: Lijn 1 OF lijn 2

Sheet machines keuken
A2: Machine | B2: aantal | C2: opmerking
A4: Gernal | B4: 1 | C4: pastakoker
A5: Terlet | B5: 4 | C5: Kook ketel - vertical roerwerk
A6: Berief | B6: 3 | C6: Kook ketel - horizontaal roerwerk
A7: KS menger | B7: 1 | C7: Karll Snell menger
A8: Stephan mixer klein | B8: 1 | C8: mixer
A9: Stephan mixer Groot | B9: 1 | C9: mixer met 2 messen

Sheet bottle necks
A1: Algemeen
A2: Iglo producties | B2: Info 11/03 (planning week 16) productie dezelfde week of een week vroeger
A3: Halal | B3: scheiding in Lijn + in tijd (starten met Halal of waar er geen Varken of Alcohol in zit)
A4: Kartonnage | B4: Starten op maadag met Shrink - op L2 geen vis indien mogelijk ?
A5: Kippebouten | B5: productie op Di -Wo : Levering op Donderdag leverings uur nooit gekend
A7: Keuken
B8: * Gernal : geen pasta of rijst te samen L1 & L2
B9: * DMB C2325 : max 4 producties op 1 dag
A11: Assemblage
B12: * 1 bak voorgerolde witloof bevat 60 rollen
A13: 46009
A15: WIP's | B15: * opentrekken etuis 1pers : 1000st/4h

Sheet planning decision tree
A1: Rationale | B1: Stappen
I2: Verduidelijking / opmerking
D3: Order X | I3: Order met toegewezen nummer komt binnen via Sandra met uiterste productiedatum X. Dat is altijd een vrijdag van de gewenste week waarin productie moet plaatsvinden.
D5: 1 dag =16h, vroegste start L1 is 6h00, vroegste start L2 is 6h30 | I5: L2 start in principe om 7h00 tenzij vlinder mogelijk. Einde dag is 22h, tenzij vrijdag 20h. | J5: waar info over vlinder? Wanneer wel en wanneer niet beschikbaar? | K5: Vlinder is in principe altijd beschikbaar. Alleen zin bij volle dag op L2
A8: Productie-technisch - kartonage | B8: Op welke lijn moet/mag de maaltijd geproduceerd worden? | D8: Moet op L1 | F8: Moet/mag op L2 | I8: Yvan gaat altijd eerst L1 vullen, dan L2. L1 (retail lijn) volledig geautomatiseerd, dus alles met etuis, DMH maaltijden en blue green moet op L1. L2 alles zonder etuis, manueel in omdozen. L2 voor Picard, VAT, DMB, DMC. | J8: Beperking op L2 Kan worden opgelost met nieuwe KliKlok (en shrinkmachine). L2 en CFS lijn ("L4") kunnen niet tegelijk draaien want gebruiken zelfde spiraal (spiraal 1 van L2). Andere spiraal zit al vol. Dus CFS en L2 moeten na elkaar gepland worden (alterneren). | K8: CFS vis kan via spiraal L1 / Bofrost CFS kan niet via spiraal L1. DMB moet op L2 wegens vorm schaal en bocht transportband
A11: Timing | B11: Naar welke week in de planning kijken we eerst? | D11: plan datum WEEK Y | F11: WEEK Y-1 | H11: Sandra - Elisabeth | I11: Week Y is de week waarin de productie ten laatste moet plaatsvinden. Als die week niet kan, proberen we de week daarvoor (Y-1) om zeker op tijd klaar te zijn. Als die week ook niet lukt, bespreekt Yvan met Sandra en Elisabeth welke maaltijd er voor welke klant kan verschoven worden, in functie van stock, grondstoffen, hoogdringendheid en eventueel andere overwegingen | J11: Prioritisering van klanten - is Fitmeals belangrijker dan DMC? Ranking van (groep van) 6 nummers met prioriteit.
A14: Met wat maken we de maaltijd | B14: Welk type grondstoffen zijn er nodig voor de maaltijd? | D14: Enkel grondstoffen nodig die gebruiksklaar zijn (dus geen D-1 of D-meer MEP) of diepvries? | F14: Niet op maandag of na officiële verlofdag, indien MEP in keuken D-2 of meer, dan nog dagen bijtellen | I14: * kippebouten enkel inplannen op Di-Wo of Vr; worden enkel op maandag of uitzonderlijk donderdag geleverd (donderdag mits andere leverancier). | J14: verzagen van vis kan ook veel vroeger in principe - is los van lijnbezetting - dus niet onmiddellijk relevant voor planning
A17: Productie-technisch kapvorm | D17: Kapvorm = vorig order of leeg (i.e. geen voorafgaand order op moment van inplannen) | F17: indien niet gelijk met vorig order: later/vroeger op dezelfde dag of zoek andere datum
A20: Productie-technisch | D20: Is een formaat deel voor mondini dubbel gebruik beschikbaar? | F20: L1 of L2 planning aanpassen | I20: Formaat deel enkel van belang als we twee dezelfde formaten op 2 lijnen willen draaien | J20: bottleneck is oplosbaar mits investering - komt bijna nooit voor
A22: Timing | D22: Bepaal ombouw tijd | I22: Ombouwtijd wordt bepaald door reinigingscyclus (altijd na 8h en na tweede shift), verandering van schaal, verandering van machines, verandering van lijn
D25: zelfde formaat schaal | F25: standaard 20min
D26: UK59 en C2187 | F26: standaard 20min
D27: naar/van CFS | F27: standaard 15 min
D28: ander formaat schaal | F28: standaard 30 min
D29: Leonard naar Leonard | F29: standaard 40min
A34: Productie-technisch | D34: Gernal voorrang op L1 | F34: dan geen rijst of pasta L2 | I34: Nieuwe Gernal zal dit veranderen | J34: saté op 2 lijnen tegelijkertijd gaat niet want alles met rijst of pasta is en dan is Gernal bottleneck | K34: tijdelijk
D35: eerst rijst , daarna pasta | I35: 1st rijst dan pasta: omwillen van gluten en eieren. Als je eerste pasta zou doen dan meer reinigen/ontsmetten | J35: Leonhardt in principe op L1, multifill op L2, maar kunnen eigenlijk beide op L1 of L2 gebruikt worden | K35: blijft relevant
A38: People | D38: nieuw recept | F38: niet als 1ste order v/d dag | I38: R&D en anderen moeten aanwezig zijn dus niet om 6h 's morgens
A41: Productie-technisch | D41: identificatie moeilijk product of halal productie | F41: als 1ste product opstarten | I41: Moeilijk product: bijv. lasagne waar heel veel pompen voor nodig zijn, Iglo BE witloof gratin, Iglo BE aardappel gratin. Bij halal geen varkensvlees op andere lijn
D44: Sate productie op L1 | F44: Geen Productie op L2 | H44: Productie saté in namiddag want anders ganse dag maar 1 lijn bezet | I44: Ook omgekeerd uiteraard: sate op L2 betekent geen productie van iets anders op L1. Saté wordt nu op L2 gedraaid want etiketten waaien er af op spiraal van L1 | J44: saté = bevat pinda. Pindanotenpasta: 11289900. CSB programma 135 geeft overzicht waar dat overal inzit. | K44: optimalisatie mogelijk? Beter saté op L2 aan lagere snelheid dan géén productie op L2?
A47: Personeelsbezetting assemblage | D47: Bezetting vorig order = of +1 of -1 | I47: FTE werkt 8h, Interim moet minimum 4h werken | J47: plus1 min1 regel vooral voor L2 want meer maaltijden per shift | K47: Combi 2 lijnen moet bekeken worden; totaal over 2 lijnen moet zo weinig mogelijk fluctueren
D49: allergenen = of hoger vorig order | I49: Van weinig naar meer allergenen; dus van laag risico product naar hoger risico product | J49: Van hoger naar lager risico kan, maar dan meer intense reiniging nodig (met ontsmetting).
D50: kruiscontaminatie allergenen
D53: aantal weegschalen max. 16st | I53: Gaat over weegschalen aan de assemblagelijn. Als dit een beperking is, aantal weegschalen verhogen?
C61: OPMERKINGEN
C63: * orders met hetzelfde 2nr erin samen produceren (eerst de kleinste plannen) vb 65107400 - 65107300
C64: * indien veel MEP (vb witloof garen) oppassen met sate productie (want dan maar 8h beschikbaar voor MEP)
D65: * indien Mep D-1 op gernal : voldoende tijd vrij op Gernal D-1 | J65: snap ik niet
C66: * kaasmachine voorrang L1 - extra persoon op L2 indien dubbel gebruik
C67: * productie apetito moet op L2 - etiketten waaien eraf in spiraal L1
C68: * productie C2176-1A Evolve op L2 : kan op 3200st/min (info 08/09/25)
C69: * productie frieten op 280gr L2 - waaien weg in spiraal L1 ook met minder ventilatoren (ventilator gebroken op 27/02/25)
C70: * productie frieten 400gr kan op L1 (info 08/09/25)
C71: * productie 64226400 - 6426500 - 64226600 40 min ombouw voorzien (info Guy)
C72: * eitketten DMC & VAT zonder etiketten op L1 (in WIP) / DMH & Soep kunnen met etiketten op L1
C73: * productie 800gr op L2 (die van L1 komt) , moet aan een lagere snelheid max snelheid 34/min
C74: * Productie blue Nasi : lijnsnelheid op 2500/min instelling lijn 50/min (1 baans) (info Tom 01/07/25) | I74: (kan op L1 etiket 10x10)
C75: * Productie blue Green Bami : lijnsnelheid op 2000/min instelling lijn 40/min (1 baans) (info Tom 01/07/25) | I75: (kan op L1 etiket 10x10)
C76: * Productie VAT & DMC niet verhogen ifv uren
C77: * H44 moet via nieuwe kliklok , schalen misvormen op oude kliklok
...

Sheet product database
A1: Product Informatie | H1: Personeel | P1: Prio Lijn | S1: Spiraal | U1: Planning | AG1: Toestellen Keuken | AM1: Toestellen Assemblage | AW1: Kartonnage | BD1: Kruiscontaminatie (enkel keuken)
A2: Product nummer | B2: Product naam | C2: schaal | D2: kapvorm | E2: karton | F2: flowpack | G2: Allergeen | H2: Assemblage L1 | I2: Assemblage L2 | J2: Kartonnage | K2: Keuken | L2: Snelheid L1 | M2: Snelheid L2 | N2: Opmerking | O2: identiek product | P2: L1 | Q2: L2 | R2: CFS | S2: L1 | T2: L2 | U2: Maandag | V2: Dinsdag | W2: Woensdag | X2: Donderdag | Y2: Vrijdag | Z2: MEP D-1 | AA2: MEP > D-1 | AB2: opstart moet | AC2: opstart kan niet | AD2: afsluit moet | AE2: afsluit kan niet | AF2: vis verzagen | AG2: Gernal (2) | AH2: Terlet (4) | AI2: Berief (3) | AJ2: KS menger (1) | AK2: Stephan mixer kl | AL2: Stephan mixer gr | AM2: Leonard (2) | AN2: weegschalen (16) | AO2: Multifill (1) | AP2: kaasstrooi(1) | AQ2: Turbo(8 enkel -3 dubbel) | AR2: Handtmann (4) | AS2: Multipond (L1) | AT2: Isihda (L2) | AU2: Grote (2) | AV2: CFS pomp (1) | AW2: Kliklok L1 | AX2: Shrink | AY2: CPS | AZ2: Kliklok L2 | BA2: Hand nipak | BB2: oude Kliklok (kooien) | BC2: kooien inpak kart | BD2: Aardnoten | BE2: Eieren | BF2: Gluten | BG2: Lupine | BH2: Melk | BI2: Mosterd | BJ2: Noten (schaalvruchten) | BK2: Schaaldieren | BL2: Selderij | BM2: Sesamzaad | BN2: Soja | BO2: Vis | BP2: Weekdieren
A3: 60920100 | B3: =VLOOKUP($A3,[1]maaltijden!$A$1:$IV$65536,4,FALSE) -> DMB KIPPENSOEP 900G | C3: =VLOOKUP($A3,[1]maaltijden!$A$1:$IV$65536,7,FALSE) -> C2227-1H | D3: =VLOOKUP($A3,[1]maaltijden!$A$1:$IV$65536,10,FALSE) -> NVT | E3: =VLOOKUP($A3,[1]maaltijden!$A$1:$IV$65536,13,FALSE) -> DMC X 6 | F3: =IF($D3="Bedrukte folie 470x300",1,0) -> 0 | G3: =VLOOKUP($A3,[1]maaltijden!$A$1:$IV$65536,27,FALSE) -> ! ! ! | H3: =VLOOKUP($A3,[1]maaltijden!$A$1:$IV$65536,21,FALSE) -> 3 | I3: =VLOOKUP($A3,[1]maaltijden!$A$1:$IV$65536,21,FALSE) -> 3 | J3: =VLOOKUP($A3,[1]maaltijden!$A$1:$IV$65536,18,FALSE) -> 3 | K3: =VLOOKUP($A3,[1]maaltijden!$A$1:$IV$65536,17,FALSE) -> 1 | L3: =VLOOKUP($A3,[1]maaltijden!$A$1:$IV$65536,20,FALSE) -> 1750 | M3: =VLOOKUP($A3,[1]maaltijden!$A$1:$IV$65536,22,FALSE) -> 1750 | N3: 0 | O3: 0 | P3: 0 | Q3: 1 | R3: 0 | S3: 0 | T3: 1 | U3: 0 | V3: 1 | W3: 1 | X3: 1 | Y3: 1 | Z3: 0 | AA3: 0 | AB3: 0 | AC3: 0 | AD3: 0 | AE3: 1 | AF3: 0 | AG3: 0 | AH3: 1 | AI3: 0 | AJ3: 0 | AK3: 0 | AL3: 0 | AM3: 0 | AN3: =IFERROR(INDEX([2]lijnopstellingsfiche!$AP$1:$AP$65536,MATCH(A3,[2]lijnopstellingsfiche!$AQ$1:$AQ$65536,0)),"") -> - | AO3: 0 | AP3: 0 | AQ3: 2 | AR3: 0 | AS3: 0 | AT3: 0 | AU3: 0 | AV3: 0 | AW3: 0 | AX3: 0 | AY3: 1 | AZ3: 0 | BA3: 1 | BB3: 0 | BC3: 0 | BD3: =VLOOKUP($A3,'[3]allergenen 6nr'!$A$1:$O$1310,3,FALSE) -> - | BE3: =VLOOKUP($A3,'[3]allergenen 6nr'!$A$1:$O$1310,4,FALSE) -> X | BF3: =VLOOKUP($A3,'[3]allergenen 6nr'!$A$1:$O$1310,5,FALSE) -> + | BG3: =VLOOKUP($A3,'[3]allergenen 6nr'!$A$1:$O$1310,6,FALSE) -> X | BH3: =VLOOKUP($A3,'[3]allergenen 6nr'!$A$1:$O$1310,7,FALSE) -> + | BI3: =VLOOKUP($A3,'[3]allergenen 6nr'!$A$1:$O$1310,8,FALSE) -> X | BJ3: =VLOOKUP($A3,'[3]allergenen 6nr'!$A$1:$O$1310,9,FALSE) -> - | BK3: =VLOOKUP($A3,'[3]allergenen 6nr'!$A$1:$O$1310,10,FALSE) -> - | BL3: =VLOOKUP($A3,'[3]allergenen 6nr'!$A$1:$O$1310,11,FALSE) -> + | BM3: =VLOOKUP($A3,'[3]allergenen 6nr'!$A$1:$O$1310,12,FALSE) -> - | BN3: =VLOOKUP($A3,'[3]allergenen 6nr'!$A$1:$O$1310,13,FALSE) -> X | BO3: =VLOOKUP($A3,'[3]allergenen 6nr'!$A$1:$O$1310,14,FALSE) -> - | BP3: =VLOOKUP($A3,'[3]allergenen 6nr'!$A$1:$O$1310,15,FALSE) -> -
A4: 60920200 | B4: =VLOOKUP($A4,[1]maaltijden!$A$1:$IV$65536,4,FALSE) -> DMB PREISOEP 900G | C4: =VLOOKUP($A4,[1]maaltijden!$A$1:$IV$65536,7,FALSE) -> C2227-1H | D4: =VLOOKUP($A4,[1]maaltijden!$A$1:$IV$65536,10,FALSE) -> NVT | E4: =VLOOKUP($A4,[1]maaltijden!$A$1:$IV$65536,13,FALSE) -> DMC X 6 | F4: =IF($D4="Bedrukte folie 470x300",1,0) -> 0 | G4: =VLOOKUP($A4,[1]maaltijden!$A$1:$IV$65536,27,FALSE) -> ! ! ! | H4: =VLOOKUP($A4,[1]maaltijden!$A$1:$IV$65536,21,FALSE) -> 1 | I4: =VLOOKUP($A4,[1]maaltijden!$A$1:$IV$65536,21,FALSE) -> 1 | J4: =VLOOKUP($A4,[1]maaltijden!$A$1:$IV$65536,18,FALSE) -> 3 | K4: =VLOOKUP($A4,[1]maaltijden!$A$1:$IV$65536,17,FALSE) -> 2 | L4: =VLOOKUP($A4,[1]maaltijden!$A$1:$IV$65536,20,FALSE) -> 1750 | M4: =VLOOKUP($A4,[1]maaltijden!$A$1:$IV$65536,22,FALSE) -> 1750 | N4: 0 | O4: 0 | P4: 0 | Q4: 1 | R4: 0 | S4: 0 | T4: 1 | U4: 0 | V4: 1 | W4: 1 | X4: 1 | Y4: 1 | Z4: 0 | AA4: 0 | AB4: 0 | AC4: 0 | AD4: 0 | AE4: 1 | AF4: 0 | AG4: 0 | AH4: 0 | AI4: 1 | AJ4: 0 | AK4: 0 | AL4: 0 | AM4: 0 | AN4: =IFERROR(INDEX([2]lijnopstellingsfiche!$AP$1:$AP$65536,MATCH(A4,[2]lijnopstellingsfiche!$AQ$1:$AQ$65536,0)),"") -> - | AO4: 0 | AP4: 0 | AQ4: 2 | AR4: 0 | AS4: 0 | AT4: 0 | AU4: 0 | AV4: 0 | AW4: 0 | AX4: 0 | AY4: 1 | AZ4: 0 | BA4: 1 | BB4: 0 | BC4: 0 | BD4: =VLOOKUP($A4,'[3]allergenen 6nr'!$A$1:$O$1310,3,FALSE) -> - | BE4: =VLOOKUP($A4,'[3]allergenen 6nr'!$A$1:$O$1310,4,FALSE) -> - | BF4: =VLOOKUP($A4,'[3]allergenen 6nr'!$A$1:$O$1310,5,FALSE) -> + | BG4: =VLOOKUP($A4,'[3]allergenen 6nr'!$A$1:$O$1310,6,FALSE) -> - | BH4: =VLOOKUP($A4,'[3]allergenen 6nr'!$A$1:$O$1310,7,FALSE) -> - | BI4: =VLOOKUP($A4,'[3]allergenen 6nr'!$A$1:$O$1310,8,FALSE) -> - | BJ4: =VLOOKUP($A4,'[3]allergenen 6nr'!$A$1:$O$1310,9,FALSE) -> - | BK4: =VLOOKUP($A4,'[3]allergenen 6nr'!$A$1:$O$1310,10,FALSE) -> - | BL4: =VLOOKUP($A4,'[3]allergenen 6nr'!$A$1:$O$1310,11,FALSE) -> + | BM4: =VLOOKUP($A4,'[3]allergenen 6nr'!$A$1:$O$1310,12,FALSE) -> - | BN4: =VLOOKUP($A4,'[3]allergenen 6nr'!$A$1:$O$1310,13,FALSE) -> - | BO4: =VLOOKUP($A4,'[3]allergenen 6nr'!$A$1:$O$1310,14,FALSE) -> - | BP4: =VLOOKUP($A4,'[3]allergenen 6nr'!$A$1:$O$1310,15,FALSE) -> -
A5: 60920400 | B5: =VLOOKUP($A5,[1]maaltijden!$A$1:$IV$65536,4,FALSE) -> DMB TOMATENSOEP MET BALLETJES 1000G | C5: =VLOOKUP($A5,[1]maaltijden!$A$1:$IV$65536,7,FALSE) -> C2227-1H | D5: =VLOOKUP($A5,[1]maaltijden!$A$1:$IV$65536,10,FALSE) -> NVT | E5: =VLOOKUP($A5,[1]maaltijden!$A$1:$IV$65536,13,FALSE) -> DMC X 6 | F5: =IF($D5="Bedrukte folie 470x300",1,0) -> 0 | G5: =VLOOKUP($A5,[1]maaltijden!$A$1:$IV$65536,27,FALSE) -> ! ! ! | H5: =VLOOKUP($A5,[1]maaltijden!$A$1:$IV$65536,21,FALSE) -> 3 | I5: =VLOOKUP($A5,[1]maaltijden!$A$1:$IV$65536,21,FALSE) -> 3 | J5: =VLOOKUP($A5,[1]maaltijden!$A$1:$IV$65536,18,FALSE) -> 3 | K5: =VLOOKUP($A5,[1]maaltijden!$A$1:$IV$65536,17,FALSE) -> 2 | L5: =VLOOKUP($A5,[1]maaltijden!$A$1:$IV$65536,20,FALSE) -> 1500 | M5: =VLOOKUP($A5,[1]maaltijden!$A$1:$IV$65536,22,FALSE) -> 1500 | N5: 0 | O5: 0 | P5: 0 | Q5: 1 | R5: 0 | S5: 0 | T5: 1 | U5: 0 | V5: 1 | W5: 1 | X5: 1 | Y5: 1 | Z5: 0 | AA5: 0 | AB5: 0 | AC5: 0 | AD5: 0 | AE5: 1 | AF5: 0 | AG5: 0 | AH5: 0 | AI5: 1 | AJ5: 0 | AK5: 0 | AL5: 1 | AM5: 0 | AN5: =IFERROR(INDEX([2]lijnopstellingsfiche!$AP$1:$AP$65536,MATCH(A5,[2]lijnopstellingsfiche!$AQ$1:$AQ$65536,0)),"") -> 1 | AO5: 0 | AP5: 0 | AQ5: 2 | AR5: 0 | AS5: 0 | AT5: 1 | AU5: 0 | AV5: 0 | AW5: 0 | AX5: 0 | AY5: 1 | AZ5: 0 | BA5: 1 | BB5: 0 | BC5: 0 | BD5: =VLOOKUP($A5,'[3]allergenen 6nr'!$A$1:$O$1310,3,FALSE) -> - | BE5: =VLOOKUP($A5,'[3]allergenen 6nr'!$A$1:$O$1310,4,FALSE) -> X | BF5: =VLOOKUP($A5,'[3]allergenen 6nr'!$A$1:$O$1310,5,FALSE) -> + | BG5: =VLOOKUP($A5,'[3]allergenen 6nr'!$A$1:$O$1310,6,FALSE) -> - | BH5: =VLOOKUP($A5,'[3]allergenen 6nr'!$A$1:$O$1310,7,FALSE) -> X | BI5: =VLOOKUP($A5,'[3]allergenen 6nr'!$A$1:$O$1310,8,FALSE) -> X | BJ5: =VLOOKUP($A5,'[3]allergenen 6nr'!$A$1:$O$1310,9,FALSE) -> - | BK5: =VLOOKUP($A5,'[3]allergenen 6nr'!$A$1:$O$1310,10,FALSE) -> X | BL5: =VLOOKUP($A5,'[3]allergenen 6nr'!$A$1:$O$1310,11,FALSE) -> + | BM5: =VLOOKUP($A5,'[3]allergenen 6nr'!$A$1:$O$1310,12,FALSE) -> - | BN5: =VLOOKUP($A5,'[3]allergenen 6nr'!$A$1:$O$1310,13,FALSE) -> X | BO5: =VLOOKUP($A5,'[3]allergenen 6nr'!$A$1:$O$1310,14,FALSE) -> X | BP5: =VLOOKUP($A5,'[3]allergenen 6nr'!$A$1:$O$1310,15,FALSE) -> X
A6: 60920500 | B6: =VLOOKUP($A6,[1]maaltijden!$A$1:$IV$65536,4,FALSE) -> DMB ERWTENSOEP MET GEROOKTE SPEKJES 900G | C6: =VLOOKUP($A6,[1]maaltijden!$A$1:$IV$65536,7,FALSE) -> C2227-1H | D6: =VLOOKUP($A6,[1]maaltijden!$A$1:$IV$65536,10,FALSE) -> NVT | E6: =VLOOKUP($A6,[1]maaltijden!$A$1:$IV$65536,13,FALSE) -> DMC X 6 | F6: =IF($D6="Bedrukte folie 470x300",1,0) -> 0 | G6: =VLOOKUP($A6,[1]maaltijden!$A$1:$IV$65536,27,FALSE) -> ! ! ! | H6: =VLOOKUP($A6,[1]maaltijden!$A$1:$IV$65536,21,FALSE) -> 1 | I6: =VLOOKUP($A6,[1]maaltijden!$A$1:$IV$65536,21,FALSE) -> 1 | J6: =VLOOKUP($A6,[1]maaltijden!$A$1:$IV$65536,18,FALSE) -> 3 | K6: =VLOOKUP($A6,[1]maaltijden!$A$1:$IV$65536,17,FALSE) -> 2 | L6: =VLOOKUP($A6,[1]maaltijden!$A$1:$IV$65536,20,FALSE) -> 1750 | M6: =VLOOKUP($A6,[1]maaltijden!$A$1:$IV$65536,22,FALSE) -> 1750 | N6: 0 | O6: 0 | P6: 0 | Q6: 1 | R6: 0 | S6: 0 | T6: 1 | U6: 0 | V6: 1 | W6: 1 | X6: 1 | Y6: 1 | Z6: 1 | AA6: 0 | AB6: 0 | AC6: 0 | AD6: 0 | AE6: 1 | AF6: 0 | AG6: 0 | AH6: 0 | AI6: 1 | AJ6: 0 | AK6: 0 | AL6: 1 | AM6: 0 | AN6: =IFERROR(INDEX([2]lijnopstellingsfiche!$AP$1:$AP$65536,MATCH(A6,[2]lijnopstellingsfiche!$AQ$1:$AQ$65536,0)),"") -> - | AO6: 0 | AP6: 0 | AQ6: 2 | AR6: 0 | AS6: 0 | AT6: 0 | AU6: 0 | AV6: 0 | AW6: 0 | AX6: 0 | AY6: 1 | AZ6: 0 | BA6: 1 | BB6: 0 | BC6: 0 | BD6: =VLOOKUP($A6,'[3]allergenen 6nr'!$A$1:$O$1310,3,FALSE) -> - | BE6: =VLOOKUP($A6,'[3]allergenen 6nr'!$A$1:$O$1310,4,FALSE) -> - | BF6: =VLOOKUP($A6,'[3]allergenen 6nr'!$A$1:$O$1310,5,FALSE) -> X | BG6: =VLOOKUP($A6,'[3]allergenen 6nr'!$A$1:$O$1310,6,FALSE) -> - | BH6: =VLOOKUP($A6,'[3]allergenen 6nr'!$A$1:$O$1310,7,FALSE) -> - | BI6: =VLOOKUP($A6,'[3]allergenen 6nr'!$A$1:$O$1310,8,FALSE) -> - | BJ6: =VLOOKUP($A6,'[3]allergenen 6nr'!$A$1:$O$1310,9,FALSE) -> - | BK6: =VLOOKUP($A6,'[3]allergenen 6nr'!$A$1:$O$1310,10,FALSE) -> - | BL6: =VLOOKUP($A6,'[3]allergenen 6nr'!$A$1:$O$1310,11,FALSE) -> + | BM6: =VLOOKUP($A6,'[3]allergenen 6nr'!$A$1:$O$1310,12,FALSE) -> - | BN6: =VLOOKUP($A6,'[3]allergenen 6nr'!$A$1:$O$1310,13,FALSE) -> X | BO6: =VLOOKUP($A6,'[3]allergenen 6nr'!$A$1:$O$1310,14,FALSE) -> - | BP6: =VLOOKUP($A6,'[3]allergenen 6nr'!$A$1:$O$1310,15,FALSE) -> -
A7: 60920600 | B7: =VLOOKUP($A7,[1]maaltijden!$A$1:$IV$65536,4,FALSE) -> DMB KERVELSOEP 900G | C7: =VLOOKUP($A7,[1]maaltijden!$A$1:$IV$65536,7,FALSE) -> C2227-1H | D7: =VLOOKUP($A7,[1]maaltijden!$A$1:$IV$65536,10,FALSE) -> NVT | E7: =VLOOKUP($A7,[1]maaltijden!$A$1:$IV$65536,13,FALSE) -> DMC X 6 | F7: =IF($D7="Bedrukte folie 470x300",1,0) -> 0 | G7: =VLOOKUP($A7,[1]maaltijden!$A$1:$IV$65536,27,FALSE) -> ! ! ! | H7: =VLOOKUP($A7,[1]maaltijden!$A$1:$IV$65536,21,FALSE) -> 1 | I7: =VLOOKUP($A7,[1]maaltijden!$A$1:$IV$65536,21,FALSE) -> 1 | J7: =VLOOKUP($A7,[1]maaltijden!$A$1:$IV$65536,18,FALSE) -> 3 | K7: =VLOOKUP($A7,[1]maaltijden!$A$1:$IV$65536,17,FALSE) -> 2 | L7: =VLOOKUP($A7,[1]maaltijden!$A$1:$IV$65536,20,FALSE) -> 1750 | M7: =VLOOKUP($A7,[1]maaltijden!$A$1:$IV$65536,22,FALSE) -> 1750 | N7: 0 | O7: 0 | P7: 0 | Q7: 1 | R7: 0 | S7: 0 | T7: 1 | U7: 0 | V7: 1 | W7: 1 | X7: 1 | Y7: 1 | Z7: 0 | AA7: 0 | AB7: 0 | AC7: 0 | AD7: 0 | AE7: 1 | AF7: 0 | AG7: 0 | AH7: 0 | AI7: 1 | AJ7: 0 | AK7: 0 | AL7: 1 | AM7: 0 | AN7: =IFERROR(INDEX([2]lijnopstellingsfiche!$AP$1:$AP$65536,MATCH(A7,[2]lijnopstellingsfiche!$AQ$1:$AQ$65536,0)),"") -> - | AO7: 0 | AP7: 0 | AQ7: 2 | AR7: 0 | AS7: 0 | AT7: 0 | AU7: 0 | AV7: 0 | AW7: 0 | AX7: 0 | AY7: 1 | AZ7: 0 | BA7: 1 | BB7: 0 | BC7: 0 | BD7: =VLOOKUP($A7,'[3]allergenen 6nr'!$A$1:$O$1310,3,FALSE) -> - | BE7: =VLOOKUP($A7,'[3]allergenen 6nr'!$A$1:$O$1310,4,FALSE) -> - | BF7: =VLOOKUP($A7,'[3]allergenen 6nr'!$A$1:$O$1310,5,FALSE) -> + | BG7: =VLOOKUP($A7,'[3]allergenen 6nr'!$A$1:$O$1310,6,FALSE) -> - | BH7: =VLOOKUP($A7,'[3]allergenen 6nr'!$A$1:$O$1310,7,FALSE) -> + | BI7: =VLOOKUP($A7,'[3]allergenen 6nr'!$A$1:$O$1310,8,FALSE) -> - | BJ7: =VLOOKUP($A7,'[3]allergenen 6nr'!$A$1:$O$1310,9,FALSE) -> - | BK7: =VLOOKUP($A7,'[3]allergenen 6nr'!$A$1:$O$1310,10,FALSE) -> - | BL7: =VLOOKUP($A7,'[3]allergenen 6nr'!$A$1:$O$1310,11,FALSE) -> + | BM7: =VLOOKUP($A7,'[3]allergenen 6nr'!$A$1:$O$1310,12,FALSE) -> - | BN7: =VLOOKUP($A7,'[3]allergenen 6nr'!$A$1:$O$1310,13,FALSE) -> - | BO7: =VLOOKUP($A7,'[3]allergenen 6nr'!$A$1:$O$1310,14,FALSE) -> - | BP7: =VLOOKUP($A7,'[3]allergenen 6nr'!$A$1:$O$1310,15,FALSE) -> -
A8: 60920700 | B8: =VLOOKUP($A8,[1]maaltijden!$A$1:$IV$65536,4,FALSE) -> DMB GROENTENSOEP 900G | C8: =VLOOKUP($A8,[1]maaltijden!$A$1:$IV$65536,7,FALSE) -> C2227-1H | D8: =VLOOKUP($A8,[1]maaltijden!$A$1:$IV$65536,10,FALSE) -> NVT | E8: =VLOOKUP($A8,[1]maaltijden!$A$1:$IV$65536,13,FALSE) -> DMC X 6 | F8: =IF($D8="Bedrukte folie 470x300",1,0) -> 0 | G8: =VLOOKUP($A8,[1]maaltijden!$A$1:$IV$65536,27,FALSE) -> ! ! ! | H8: =VLOOKUP($A8,[1]maaltijden!$A$1:$IV$65536,21,FALSE) -> 2 | I8: =VLOOKUP($A8,[1]maaltijden!$A$1:$IV$65536,21,FALSE) -> 2 | J8: =VLOOKUP($A8,[1]maaltijden!$A$1:$IV$65536,18,FALSE) -> 3 | K8: =VLOOKUP($A8,[1]maaltijden!$A$1:$IV$65536,17,FALSE) -> 2 | L8: =VLOOKUP($A8,[1]maaltijden!$A$1:$IV$65536,20,FALSE) -> 1750 | M8: =VLOOKUP($A8,[1]maaltijden!$A$1:$IV$65536,22,FALSE) -> 1750 | N8: 0 | O8: 0 | P8: 0 | Q8: 1 | R8: 0 | S8: 0 | T8: 1 | U8: 0 | V8: 1 | W8: 1 | X8: 1 | Y8: 1 | Z8: 0 | AA8: 0 | AB8: 0 | AC8: 0 | AD8: 0 | AE8: 1 | AF8: 0 | AG8: 0 | AH8: 1 | AI8: 0 | AJ8: 0 | AK8: 0 | AL8: 0 | AM8: 0 | AN8: =IFERROR(INDEX([2]lijnopstellingsfiche!$AP$1:$AP$65536,MATCH(A8,[2]lijnopstellingsfiche!$AQ$1:$AQ$65536,0)),"") -> - | AO8: 0 | AP8: 0 | AQ8: 2 | AR8: 0 | AS8: 0 | AT8: 0 | AU8: 0 | AV8: 0 | AW8: 0 | AX8: 0 | AY8: 1 | AZ8: 0 | BA8: 1 | BB8: 0 | BC8: 0 | BD8: =VLOOKUP($A8,'[3]allergenen 6nr'!$A$1:$O$1310,3,FALSE) -> - | BE8: =VLOOKUP($A8,'[3]allergenen 6nr'!$A$1:$O$1310,4,FALSE) -> X | BF8: =VLOOKUP($A8,'[3]allergenen 6nr'!$A$1:$O$1310,5,FALSE) -> + | BG8: =VLOOKUP($A8,'[3]allergenen 6nr'!$A$1:$O$1310,6,FALSE) -> X | BH8: =VLOOKUP($A8,'[3]allergenen 6nr'!$A$1:$O$1310,7,FALSE) -> - | BI8: =VLOOKUP($A8,'[3]allergenen 6nr'!$A$1:$O$1310,8,FALSE) -> X | BJ8: =VLOOKUP($A8,'[3]allergenen 6nr'!$A$1:$O$1310,9,FALSE) -> - | BK8: =VLOOKUP($A8,'[3]allergenen 6nr'!$A$1:$O$1310,10,FALSE) -> - | BL8: =VLOOKUP($A8,'[3]allergenen 6nr'!$A$1:$O$1310,11,FALSE) -> + | BM8: =VLOOKUP($A8,'[3]allergenen 6nr'!$A$1:$O$1310,12,FALSE) -> - | BN8: =VLOOKUP($A8,'[3]allergenen 6nr'!$A$1:$O$1310,13,FALSE) -> X | BO8: =VLOOKUP($A8,'[3]allergenen 6nr'!$A$1:$O$1310,14,FALSE) -> - | BP8: =VLOOKUP($A8,'[3]allergenen 6nr'!$A$1:$O$1310,15,FALSE) -> -
A9: 60920800 | B9: =VLOOKUP($A9,[1]maaltijden!$A$1:$IV$65536,4,FALSE) -> DMB TOMATENVELOUTE 900G | C9: =VLOOKUP($A9,[1]maaltijden!$A$1:$IV$65536,7,FALSE) -> C2227-1H | D9: =VLOOKUP($A9,[1]maaltijden!$A$1:$IV$65536,10,FALSE) -> NVT | E9: =VLOOKUP($A9,[1]maaltijden!$A$1:$IV$65536,13,FALSE) -> DMC X 6 | F9: =IF($D9="Bedrukte folie 470x300",1,0) -> 0 | G9: =VLOOKUP($A9,[1]maaltijden!$A$1:$IV$65536,27,FALSE) -> ! ! | H9: =VLOOKUP($A9,[1]maaltijden!$A$1:$IV$65536,21,FALSE) -> 1 | I9: =VLOOKUP($A9,[1]maaltijden!$A$1:$IV$65536,21,FALSE) -> 1 | J9: =VLOOKUP($A9,[1]maaltijden!$A$1:$IV$65536,18,FALSE) -> 3 | K9: =VLOOKUP($A9,[1]maaltijden!$A$1:$IV$65536,17,FALSE) -> 2 | L9: =VLOOKUP($A9,[1]maaltijden!$A$1:$IV$65536,20,FALSE) -> 1750 | M9: =VLOOKUP($A9,[1]maaltijden!$A$1:$IV$65536,22,FALSE) -> 1750 | N9: 0 | O9: 0 | P9: 0 | Q9: 1 | R9: 0 | S9: 0 | T9: 1 | U9: 0 | V9: 1 | W9: 1 | X9: 1 | Y9: 1 | Z9: 0 | AA9: 0 | AB9: 0 | AC9: 0 | AD9: 0 | AE9: 1 | AF9: 0 | AG9: 0 | AH9: 0 | AI9: 1 | AJ9: 0 | AK9: 0 | AL9: 1 | AM9: 0 | AN9: =IFERROR(INDEX([2]lijnopstellingsfiche!$AP$1:$AP$65536,MATCH(A9,[2]lijnopstellingsfiche!$AQ$1:$AQ$65536,0)),"") -> - | AO9: 0 | AP9: 0 | AQ9: 2 | AR9: 0 | AS9: 0 | AT9: 0 | AU9: 0 | AV9: 0 | AW9: 0 | AX9: 0 | AY9: 1 | AZ9: 0 | BA9: 1 | BB9: 0 | BC9: 0 | BD9: =VLOOKUP($A9,'[3]allergenen 6nr'!$A$1:$O$1310,3,FALSE) -> - | BE9: =VLOOKUP($A9,'[3]allergenen 6nr'!$A$1:$O$1310,4,FALSE) -> - | BF9: =VLOOKUP($A9,'[3]allergenen 6nr'!$A$1:$O$1310,5,FALSE) -> + | BG9: =VLOOKUP($A9,'[3]allergenen 6nr'!$A$1:$O$1310,6,FALSE) -> - | BH9: =VLOOKUP($A9,'[3]allergenen 6nr'!$A$1:$O$1310,7,FALSE) -> + | BI9: =VLOOKUP($A9,'[3]allergenen 6nr'!$A$1:$O$1310,8,FALSE) -> - | BJ9: =VLOOKUP($A9,'[3]allergenen 6nr'!$A$1:$O$1310,9,FALSE) -> - | BK9: =VLOOKUP($A9,'[3]allergenen 6nr'!$A$1:$O$1310,10,FALSE) -> - | BL9: =VLOOKUP($A9,'[3]allergenen 6nr'!$A$1:$O$1310,11,FALSE) -> - | BM9: =VLOOKUP($A9,'[3]allergenen 6nr'!$A$1:$O$1310,12,FALSE) -> - | BN9: =VLOOKUP($A9,'[3]allergenen 6nr'!$A$1:$O$1310,13,FALSE) -> - | BO9: =VLOOKUP($A9,'[3]allergenen 6nr'!$A$1:$O$1310,14,FALSE) -> - | BP9: =VLOOKUP($A9,'[3]allergenen 6nr'!$A$1:$O$1310,15,FALSE) -> -
A10: 60920900 | B10: =VLOOKUP($A10,[1]maaltijden!$A$1:$IV$65536,4,FALSE) -> DMB POMPOENSOEP 900G | C10: =VLOOKUP($A10,[1]maaltijden!$A$1:$IV$65536,7,FALSE) -> C2227-1H | D10: =VLOOKUP($A10,[1]maaltijden!$A$1:$IV$65536,10,FALSE) -> NVT | E10: =VLOOKUP($A10,[1]maaltijden!$A$1:$IV$65536,13,FALSE) -> DMC X 6 | F10: =IF($D10="Bedrukte folie 470x300",1,0) -> 0 | G10: =VLOOKUP($A10,[1]maaltijden!$A$1:$IV$65536,27,FALSE) -> ! ! | H10: =VLOOKUP($A10,[1]maaltijden!$A$1:$IV$65536,21,FALSE) -> 1 | I10: =VLOOKUP($A10,[1]maaltijden!$A$1:$IV$65536,21,FALSE) -> 1 | J10: =VLOOKUP($A10,[1]maaltijden!$A$1:$IV$65536,18,FALSE) -> 3 | K10: =VLOOKUP($A10,[1]maaltijden!$A$1:$IV$65536,17,FALSE) -> 2 | L10: =VLOOKUP($A10,[1]maaltijden!$A$1:$IV$65536,20,FALSE) -> 1750 | M10: =VLOOKUP($A10,[1]maaltijden!$A$1:$IV$65536,22,FALSE) -> 1750 | N10: 0 | O10: 0 | P10: 0 | Q10: 1 | R10: 0 | S10: 0 | T10: 1 | U10: 1 | V10: 1 | W10: 1 | X10: 1 | Y10: 1 | Z10: 0 | AA10: 0 | AB10: 0 | AC10: 0 | AD10: 0 | AE10: 0 | AF10: 0 | AG10: 0 | AH10: 0 | AI10: 1 | AJ10: 0 | AK10: 0 | AL10: 1 | AM10: 0 | AN10: =IFERROR(INDEX([2]lijnopstellingsfiche!$AP$1:$AP$65536,MATCH(A10,[2]lijnopstellingsfiche!$AQ$1:$AQ$65536,0)),"") -> - | AO10: 0 | AP10: 0 | AQ10: 2 | AR10: 0 | AS10: 0 | AT10: 0 | AU10: 0 | AV10: 0 | AW10: 0 | AX10: 0 | AY10: 1 | AZ10: 0 | BA10: 1 | BB10: 0 | BC10: 0 | BD10: =VLOOKUP($A10,'[3]allergenen 6nr'!$A$1:$O$1310,3,FALSE) -> - | BE10: =VLOOKUP($A10,'[3]allergenen 6nr'!$A$1:$O$1310,4,FALSE) -> - | BF10: =VLOOKUP($A10,'[3]allergenen 6nr'!$A$1:$O$1310,5,FALSE) -> X | BG10: =VLOOKUP($A10,'[3]allergenen 6nr'!$A$1:$O$1310,6,FALSE) -> - | BH10: =VLOOKUP($A10,'[3]allergenen 6nr'!$A$1:$O$1310,7,FALSE) -> + | BI10: =VLOOKUP($A10,'[3]allergenen 6nr'!$A$1:$O$1310,8,FALSE) -> X | BJ10: =VLOOKUP($A10,'[3]allergenen 6nr'!$A$1:$O$1310,9,FALSE) -> - | BK10: =VLOOKUP($A10,'[3]allergenen 6nr'!$A$1:$O$1310,10,FALSE) -> - | BL10: =VLOOKUP($A10,'[3]allergenen 6nr'!$A$1:$O$1310,11,FALSE) -> X | BM10: =VLOOKUP($A10,'[3]allergenen 6nr'!$A$1:$O$1310,12,FALSE) -> - | BN10: =VLOOKUP($A10,'[3]allergenen 6nr'!$A$1:$O$1310,13,FALSE) -> - | BO10: =VLOOKUP($A10,'[3]allergenen 6nr'!$A$1:$O$1310,14,FALSE) -> - | BP10: =VLOOKUP($A10,'[3]allergenen 6nr'!$A$1:$O$1310,15,FALSE) -> -
A11: 60921000 | B11: =VLOOKUP($A11,[1]maaltijden!$A$1:$IV$65536,4,FALSE) -> DMB BROCCOLISOEP 900G | C11: =VLOOKUP($A11,[1]maaltijden!$A$1:$IV$65536,7,FALSE) -> C2227-1H | D11: =VLOOKUP($A11,[1]maaltijden!$A$1:$IV$65536,10,FALSE) -> NVT | E11: =VLOOKUP($A11,[1]maaltijden!$A$1:$IV$65536,13,FALSE) -> DMC X 6 | F11: =IF($D11="Bedrukte folie 470x300",1,0) -> 0 | G11: =VLOOKUP($A11,[1]maaltijden!$A$1:$IV$65536,27,FALSE) -> ! ! ! | H11: =VLOOKUP($A11,[1]maaltijden!$A$1:$IV$65536,21,FALSE) -> 1 | I11: =VLOOKUP($A11,[1]maaltijden!$A$1:$IV$65536,21,FALSE) -> 1 | J11: =VLOOKUP($A11,[1]maaltijden!$A$1:$IV$65536,18,FALSE) -> 3 | K11: =VLOOKUP($A11,[1]maaltijden!$A$1:$IV$65536,17,FALSE) -> 2 | L11: =VLOOKUP($A11,[1]maaltijden!$A$1:$IV$65536,20,FALSE) -> 1750 | M11: =VLOOKUP($A11,[1]maaltijden!$A$1:$IV$65536,22,FALSE) -> 1750 | N11: 0 | O11: 0 | P11: 0 | Q11: 1 | R11: 0 | S11: 0 | T11: 1 | U11: 0 | V11: 1 | W11: 1 | X11: 1 | Y11: 1 | Z11: 0 | AA11: 0 | AB11: 0 | AC11: 0 | AD11: 0 | AE11: 1 | AF11: 0 | AG11: 0 | AH11: 0 | AI11: 1 | AJ11: 0 | AK11: 0 | AL11: 1 | AM11: 0 | AN11: =IFERROR(INDEX([2]lijnopstellingsfiche!$AP$1:$AP$65536,MATCH(A11,[2]lijnopstellingsfiche!$AQ$1:$AQ$65536,0)),"") -> - | AO11: 0 | AP11: 0 | AQ11: 2 | AR11: 0 | AS11: 0 | AT11: 0 | AU11: 0 | AV11: 0 | AW11: 0 | AX11: 0 | AY11: 1 | AZ11: 0 | BA11: 1 | BB11: 0 | BC11: 0 | BD11: =VLOOKUP($A11,'[3]allergenen 6nr'!$A$1:$O$1310,3,FALSE) -> - | BE11: =VLOOKUP($A11,'[3]allergenen 6nr'!$A$1:$O$1310,4,FALSE) -> - | BF11: =VLOOKUP($A11,'[3]allergenen 6nr'!$A$1:$O$1310,5,FALSE) -> + | BG11: =VLOOKUP($A11,'[3]allergenen 6nr'!$A$1:$O$1310,6,FALSE) -> - | BH11: =VLOOKUP($A11,'[3]allergenen 6nr'!$A$1:$O$1310,7,FALSE) -> + | BI11: =VLOOKUP($A11,'[3]allergenen 6nr'!$A$1:$O$1310,8,FALSE) -> - | BJ11: =VLOOKUP($A11,'[3]allergenen 6nr'!$A$1:$O$1310,9,FALSE) -> - | BK11: =VLOOKUP($A11,'[3]allergenen 6nr'!$A$1:$O$1310,10,FALSE) -> - | BL11: =VLOOKUP($A11,'[3]allergenen 6nr'!$A$1:$O$1310,11,FALSE) -> + | BM11: =VLOOKUP($A11,'[3]allergenen 6nr'!$A$1:$O$1310,12,FALSE) -> - | BN11: =VLOOKUP($A11,'[3]allergenen 6nr'!$A$1:$O$1310,13,FALSE) -> - | BO11: =VLOOKUP($A11,'[3]allergenen 6nr'!$A$1:$O$1310,14,FALSE) -> - | BP11: =VLOOKUP($A11,'[3]allergenen 6nr'!$A$1:$O$1310,15,FALSE) -> -
A12: 60921100 | B12: =VLOOKUP($A12,[1]maaltijden!$A$1:$IV$65536,4,FALSE) -> DMB CHAMPIGNONSOEP 900G | C12: =VLOOKUP($A12,[1]maaltijden!$A$1:$IV$65536,7,FALSE) -> C2227-1H | D12: =VLOOKUP($A12,[1]maaltijden!$A$1:$IV$65536,10,FALSE) -> NVT | E12: =VLOOKUP($A12,[1]maaltijden!$A$1:$IV$65536,13,FALSE) -> DMC X 6 | F12: =IF($D12="Bedrukte folie 470x300",1,0) -> 0 | G12: =VLOOKUP($A12,[1]maaltijden!$A$1:$IV$65536,27,FALSE) -> ! ! ! | H12: =VLOOKUP($A12,[1]maaltijden!$A$1:$IV$65536,21,FALSE) -> 1 | I12: =VLOOKUP($A12,[1]maaltijden!$A$1:$IV$65536,21,FALSE) -> 1 | J12: =VLOOKUP($A12,[1]maaltijden!$A$1:$IV$65536,18,FALSE) -> 3 | K12: =VLOOKUP($A12,[1]maaltijden!$A$1:$IV$65536,17,FALSE) -> 2 | L12: =VLOOKUP($A12,[1]maaltijden!$A$1:$IV$65536,20,FALSE) -> 1750 | M12: =VLOOKUP($A12,[1]maaltijden!$A$1:$IV$65536,22,FALSE) -> 1750 | N12: 0 | O12: 0 | P12: 0 | Q12: 1 | R12: 0 | S12: 0 | T12: 1 | U12: 1 | V12: 1 | W12: 1 | X12: 1 | Y12: 1 | Z12: 0 | AA12: 0 | AB12: 0 | AC12: 0 | AD12: 0 | AE12: 0 | AF12: 0 | AG12: 0 | AH12: 0 | AI12: 1 | AJ12: 0 | AK12: 0 | AL12: 1 | AM12: 0 | AN12: =IFERROR(INDEX([2]lijnopstellingsfiche!$AP$1:$AP$65536,MATCH(A12,[2]lijnopstellingsfiche!$AQ$1:$AQ$65536,0)),"") -> - | AO12: 0 | AP12: 0 | AQ12: 2 | AR12: 0 | AS12: 0 | AT12: 0 | AU12: 0 | AV12: 0 | AW12: 0 | AX12: 0 | AY12: 1 | AZ12: 0 | BA12: 1 | BB12: 0 | BC12: 0 | BD12: =VLOOKUP($A12,'[3]allergenen 6nr'!$A$1:$O$1310,3,FALSE) -> - | BE12: =VLOOKUP($A12,'[3]allergenen 6nr'!$A$1:$O$1310,4,FALSE) -> - | BF12: =VLOOKUP($A12,'[3]allergenen 6nr'!$A$1:$O$1310,5,FALSE) -> + | BG12: =VLOOKUP($A12,'[3]allergenen 6nr'!$A$1:$O$1310,6,FALSE) -> X | BH12: =VLOOKUP($A12,'[3]allergenen 6nr'!$A$1:$O$1310,7,FALSE) -> + | BI12: =VLOOKUP($A12,'[3]allergenen 6nr'!$A$1:$O$1310,8,FALSE) -> X | BJ12: =VLOOKUP($A12,'[3]allergenen 6nr'!$A$1:$O$1310,9,FALSE) -> - | BK12: =VLOOKUP($A12,'[3]allergenen 6nr'!$A$1:$O$1310,10,FALSE) -> - | BL12: =VLOOKUP($A12,'[3]allergenen 6nr'!$A$1:$O$1310,11,FALSE) -> + | BM12: =VLOOKUP($A12,'[3]allergenen 6nr'!$A$1:$O$1310,12,FALSE) -> - | BN12: =VLOOKUP($A12,'[3]allergenen 6nr'!$A$1:$O$1310,13,FALSE) -> X | BO12: =VLOOKUP($A12,'[3]allergenen 6nr'!$A$1:$O$1310,14,FALSE) -> - | BP12: =VLOOKUP($A12,'[3]allergenen 6nr'!$A$1:$O$1310,15,FALSE) -> -
A13: 60921200 | B13: =VLOOKUP($A13,[1]maaltijden!$A$1:$IV$65536,4,FALSE) -> DMB WORTELSOEP 900G | C13: =VLOOKUP($A13,[1]maaltijden!$A$1:$IV$65536,7,FALSE) -> C2227-1H | D13: =VLOOKUP($A13,[1]maaltijden!$A$1:$IV$65536,10,FALSE) -> NVT | E13: =VLOOKUP($A13,[1]maaltijden!$A$1:$IV$65536,13,FALSE) -> DMC X 6 | F13: =IF($D13="Bedrukte folie 470x300",1,0) -> 0 | G13: =VLOOKUP($A13,[1]maaltijden!$A$1:$IV$65536,27,FALSE) -> ! ! ! | H13: =VLOOKUP($A13,[1]maaltijden!$A$1:$IV$65536,21,FALSE) -> 1 | I13: =VLOOKUP($A13,[1]maaltijden!$A$1:$IV$65536,21,FALSE) -> 1 | J13: =VLOOKUP($A13,[1]maaltijden!$A$1:$IV$65536,18,FALSE) -> 3 | K13: =VLOOKUP($A13,[1]maaltijden!$A$1:$IV$65536,17,FALSE) -> 1 | L13: =VLOOKUP($A13,[1]maaltijden!$A$1:$IV$65536,20,FALSE) -> 1750 | M13: =VLOOKUP($A13,[1]maaltijden!$A$1:$IV$65536,22,FALSE) -> 1750 | N13: 0 | O13: 0 | P13: 0 | Q13: 1 | R13: 0 | S13: 1 | T13: 1 | U13: 1 | V13: 1 | W13: 1 | X13: 1 | Y13: 1 | Z13: 0 | AA13: 0 | AB13: 0 | AC13: 0 | AD13: 0 | AE13: 0 | AF13: 0 | AG13: 0 | AH13: 0 | AI13: 1 | AJ13: 0 | AK13: 0 | AL13: 1 | AM13: 0 | AN13: =IFERROR(INDEX([2]lijnopstellingsfiche!$AP$1:$AP$65536,MATCH(A13,[2]lijnopstellingsfiche!$AQ$1:$AQ$65536,0)),"") -> - | AO13: 0 | AP13: 0 | AQ13: 2 | AR13: 0 | AS13: 0 | AT13: 0 | AU13: 0 | AV13: 0 | AW13: 0 | AX13: 0 | AY13: 1 | AZ13: 0 | BA13: 1 | BB13: 0 | BC13: 0 | BD13: =VLOOKUP($A13,'[3]allergenen 6nr'!$A$1:$O$1310,3,FALSE) -> - | BE13: =VLOOKUP($A13,'[3]allergenen 6nr'!$A$1:$O$1310,4,FALSE) -> - | BF13: =VLOOKUP($A13,'[3]allergenen 6nr'!$A$1:$O$1310,5,FALSE) -> X | BG13: =VLOOKUP($A13,'[3]allergenen 6nr'!$A$1:$O$1310,6,FALSE) -> - | BH13: =VLOOKUP($A13,'[3]allergenen 6nr'!$A$1:$O$1310,7,FALSE) -> + | BI13: =VLOOKUP($A13,'[3]allergenen 6nr'!$A$1:$O$1310,8,FALSE) -> X | BJ13: =VLOOKUP($A13,'[3]allergenen 6nr'!$A$1:$O$1310,9,FALSE) -> - | BK13: =VLOOKUP($A13,'[3]allergenen 6nr'!$A$1:$O$1310,10,FALSE) -> - | BL13: =VLOOKUP($A13,'[3]allergenen 6nr'!$A$1:$O$1310,11,FALSE) -> + | BM13: =VLOOKUP($A13,'[3]allergenen 6nr'!$A$1:$O$1310,12,FALSE) -> - | BN13: =VLOOKUP($A13,'[3]allergenen 6nr'!$A$1:$O$1310,13,FALSE) -> - | BO13: =VLOOKUP($A13,'[3]allergenen 6nr'!$A$1:$O$1310,14,FALSE) -> - | BP13: =VLOOKUP($A13,'[3]allergenen 6nr'!$A$1:$O$1310,15,FALSE) -> -
A14: 60921300 | B14: =VLOOKUP($A14,[1]maaltijden!$A$1:$IV$65536,4,FALSE) -> DMB BLOEMKOOLSOEP 900G | C14: =VLOOKUP($A14,[1]maaltijden!$A$1:$IV$65536,7,FALSE) -> C2227-1H | D14: =VLOOKUP($A14,[1]maaltijden!$A$1:$IV$65536,10,FALSE) -> NVT | E14: =VLOOKUP($A14,[1]maaltijden!$A$1:$IV$65536,13,FALSE) -> DMC X 6 | F14: =IF($D14="Bedrukte folie 470x300",1,0) -> 0 | G14: =VLOOKUP($A14,[1]maaltijden!$A$1:$IV$65536,27,FALSE) -> ! ! ! | H14: =VLOOKUP($A14,[1]maaltijden!$A$1:$IV$65536,21,FALSE) -> 2 | I14: =VLOOKUP($A14,[1]maaltijden!$A$1:$IV$65536,21,FALSE) -> 2 | J14: =VLOOKUP($A14,[1]maaltijden!$A$1:$IV$65536,18,FALSE) -> 3 | K14: =VLOOKUP($A14,[1]maaltijden!$A$1:$IV$65536,17,FALSE) -> 1 | L14: =VLOOKUP($A14,[1]maaltijden!$A$1:$IV$65536,20,FALSE) -> 1750 | M14: =VLOOKUP($A14,[1]maaltijden!$A$1:$IV$65536,22,FALSE) -> 1750 | N14: 0 | O14: 0 | P14: 0 | Q14: 1 | R14: 0 | S14: 0 | T14: 1 | U14: 1 | V14: 1 | W14: 1 | X14: 1 | Y14: 1 | Z14: 0 | AA14: 0 | AB14: 0 | AC14: 0 | AD14: 0 | AE14: 0 | AF14: 0 | AG14: 0 | AH14: 1 | AI14: 0 | AJ14: 0 | AK14: 0 | AL14: 1 | AM14: 0 | AN14: =IFERROR(INDEX([2]lijnopstellingsfiche!$AP$1:$AP$65536,MATCH(A14,[2]lijnopstellingsfiche!$AQ$1:$AQ$65536,0)),"") -> - | AO14: 0 | AP14: 0 | AQ14: 2 | AR14: 0 | AS14: 0 | AT14: 0 | AU14: 0 | AV14: 0 | AW14: 0 | AX14: 0 | AY14: 1 | AZ14: 0 | BA14: 1 | BB14: 0 | BC14: 0 | BD14: =VLOOKUP($A14,'[3]allergenen 6nr'!$A$1:$O$1310,3,FALSE) -> - | BE14: =VLOOKUP($A14,'[3]allergenen 6nr'!$A$1:$O$1310,4,FALSE) -> - | BF14: =VLOOKUP($A14,'[3]allergenen 6nr'!$A$1:$O$1310,5,FALSE) -> + | BG14: =VLOOKUP($A14,'[3]allergenen 6nr'!$A$1:$O$1310,6,FALSE) -> - | BH14: =VLOOKUP($A14,'[3]allergenen 6nr'!$A$1:$O$1310,7,FALSE) -> + | BI14: =VLOOKUP($A14,'[3]allergenen 6nr'!$A$1:$O$1310,8,FALSE) -> - | BJ14: =VLOOKUP($A14,'[3]allergenen 6nr'!$A$1:$O$1310,9,FALSE) -> - | BK14: =VLOOKUP($A14,'[3]allergenen 6nr'!$A$1:$O$1310,10,FALSE) -> - | BL14: =VLOOKUP($A14,'[3]allergenen 6nr'!$A$1:$O$1310,11,FALSE) -> + | BM14: =VLOOKUP($A14,'[3]allergenen 6nr'!$A$1:$O$1310,12,FALSE) -> - | BN14: =VLOOKUP($A14,'[3]allergenen 6nr'!$A$1:$O$1310,13,FALSE) -> - | BO14: =VLOOKUP($A14,'[3]allergenen 6nr'!$A$1:$O$1310,14,FALSE) -> - | BP14: =VLOOKUP($A14,'[3]allergenen 6nr'!$A$1:$O$1310,15,FALSE) -> -
... A18: 61642800 | B18: =VLOOKUP($A18,[1]maaltijden!$A$1:$IV$65536,4,FALSE) -> COLR KIP CURRY BASMATI GROENE GROENTEN 500g | C18: =VLOOKUP($A18,[1]maaltijden!$A$1:$IV$65536,7,FALSE) -> C2227-2X | D18: =VLOOKUP($A18,[1]maaltijden!$A$1:$IV$65536,10,FALSE) -> H10 | E18: =VLOOKUP($A18,[1]maaltijden!$A$1:$IV$65536,13,FALSE) -> H10X8 | F18: =IF($D18="Bedrukte folie 470x300",1,0) -> 0 | G18: =VLOOKUP($A18,[1]maaltijden!$A$1:$IV$65536,27,FALSE) -> ! ! | H18: =VLOOKUP($A18,[1]maaltijden!$A$1:$IV$65536,21,FALSE) -> 6 | I18: =VLOOKUP($A18,[1]maaltijden!$A$1:$IV$65536,21,FALSE) -> 6 | J18: =VLOOKUP($A18,[1]maaltijden!$A$1:$IV$65536,18,FALSE) -> 2 | K18: =VLOOKUP($A18,[1]maaltijden!$A$1:$IV$65536,17,FALSE) -> 3 | L18: =VLOOKUP($A18,[1]maaltijden!$A$1:$IV$65536,20,FALSE) -> 2200 | M18: =VLOOKUP($A18,[1]maaltijden!$A$1:$IV$65536,22,FALSE) -> 2200 | N18: 0 | O18: 0 | P18: 1 | Q18: 2 | R18: 0 | S18: 1 | T18: 1 | U18: 1 | V18: 1 | W18: 1 | X18: 1 | Y18: 1 | Z18: 0 | AA18: 0 | AB18: 0 | AC18: 0 | AD18: 0 | AE18: 0 | AF18: 0 | AG18: 1 | AH18: 1 | AI18: 0 | AJ18: 1 | AK18: 0 | AL18: 0 | AM18: 1 | AN18: =IFERROR(INDEX([2]lijnopstellingsfiche!$AP$1:$AP$65536,MATCH(A18,[2]lijnopstellingsfiche!$AQ$1:$AQ$65536,0)),"") -> - | AO18: 0 | AP18: 0 | AQ18: 1 | AR18: 0 | AS18: 1 | AT18: 0 | AU18: 0 | AV18: 0 | AW18: 1 | AX18: 0 | AY18: 1 | AZ18: 1 | BA18: 0 | BB18: 1 | BC18: 0 | BD18: =VLOOKUP($A18,'[3]allergenen 6nr'!$A$1:$O$1310,3,FALSE) -> - | BE18: =VLOOKUP($A18,'[3]allergenen 6nr'!$A$1:$O$1310,4,FALSE) -> X | BF18: =VLOOKUP($A18,'[3]allergenen 6nr'!$A$1:$O$1310,5,FALSE) -> + | BG18: =VLOOKUP($A18,'[3]allergenen 6nr'!$A$1:$O$1310,6,FALSE) -> X | BH18: =VLOOKUP($A18,'[3]allergenen 6nr'!$A$1:$O$1310,7,FALSE) -> + | BI18: =VLOOKUP($A18,'[3]allergenen 6nr'!$A$1:$O$1310,8,FALSE) -> X | BJ18: =VLOOKUP($A18,'[3]allergenen 6nr'!$A$1:$O$1310,9,FALSE) -> - | BK18: =VLOOKUP($A18,'[3]allergenen 6nr'!$A$1:$O$1310,10,FALSE) -> - | BL18: =VLOOKUP($A18,'[3]allergenen 6nr'!$A$1:$O$1310,11,FALSE) -> - | BM18: =VLOOKUP($A18,'[3]allergenen 6nr'!$A$1:$O$1310,12,FALSE) -> - | BN18: =VLOOKUP($A18,'[3]allergenen 6nr'!$A$1:$O$1310,13,FALSE) -> X | BO18: =VLOOKUP($A18,'[3]allergenen 6nr'!$A$1:$O$1310,14,FALSE) -> - | BP18: =VLOOKUP($A18,'[3]allergenen 6nr'!$A$1:$O$1310,15,FALSE) -> -
A19: 61659300 | B19: =VLOOKUP($A19,[1]maaltijden!$A$1:$IV$65536,4,FALSE) -> ALDI BE RUNDSTONG BR MADEIRASAUS 750G | C19: =VLOOKUP($A19,[1]maaltijden!$A$1:$IV$65536,7,FALSE) -> C2227-1E | D19: =VLOOKUP($A19,[1]maaltijden!$A$1:$IV$65536,10,FALSE) -> H10 | E19: =VLOOKUP($A19,[1]maaltijden!$A$1:$IV$65536,13,FALSE) -> H10x18 | F19: =IF($D19="Bedrukte folie 470x300",1,0) -> 0 | G19: =VLOOKUP($A19,[1]maaltijden!$A$1:$IV$65536,27,FALSE) -> ! ! ! | H19: =VLOOKUP($A19,[1]maaltijden!$A$1:$IV$65536,21,FALSE) -> 5 | I19: =VLOOKUP($A19,[1]maaltijden!$A$1:$IV$65536,21,FALSE) -> 5 | J19: =VLOOKUP($A19,[1]maaltijden!$A$1:$IV$65536,18,FALSE) -> 2 | K19: =VLOOKUP($A19,[1]maaltijden!$A$1:$IV$65536,17,FALSE) -> 2 | L19: =VLOOKUP($A19,[1]maaltijden!$A$1:$IV$65536,20,FALSE) -> 2000 | M19: 2000 | N19: L2 : manueel afwegen | O19: 0 | P19: 1 | Q19: 0 | R19: 0 | S19: 1 | T19: 0 | U19: 0 | V19: 1 | W19: 1 | X19: 1 | Y19: 1 | Z19: 0 | AA19: 1 | AB19: 0 | AC19: 0 | AD19: 0 | AE19: 1 | AF19: 0 | AG19: 0 | AH19: 0 | AI19: 3 | AJ19: 0 | AK19: 0 | AL19: 0 | AM19: 0 | AN19: =IFERROR(INDEX([2]lijnopstellingsfiche!$AP$1:$AP$65536,MATCH(A19,[2]lijnopstellingsfiche!$AQ$1:$AQ$65536,0)),"") -> - | AO19: 0 | AP19: 0 | AQ19: 2 | AR19: 0 | AS19: 1 | AT19: 0 | AU19: 0 | AV19: 0 | AW19: 1 | AX19: 0 | AY19: 1 | AZ19: 1 | BA19: 0 | BB19: 1 | BC19: 0 | BD19: =VLOOKUP($A19,'[3]allergenen 6nr'!$A$1:$O$1310,3,FALSE) -> - | BE19: =VLOOKUP($A19,'[3]allergenen 6nr'!$A$1:$O$1310,4,FALSE) -> - | BF19: =VLOOKUP($A19,'[3]allergenen 6nr'!$A$1:$O$1310,5,FALSE) -> + | BG19: =VLOOKUP($A19,'[3]allergenen 6nr'!$A$1:$O$1310,6,FALSE) -> X | BH19: =VLOOKUP($A19,'[3]allergenen 6nr'!$A$1:$O$1310,7,FALSE) -> - | BI19: =VLOOKUP($A19,'[3]allergenen 6nr'!$A$1:$O$1310,8,FALSE) -> X | BJ19: =VLOOKUP($A19,'[3]allergenen 6nr'!$A$1:$O$1310,9,FALSE) -> - | BK19: =VLOOKUP($A19,'[3]allergenen 6nr'!$A$1:$O$1310,10,FALSE) -> - | BL19: =VLOOKUP($A19,'[3]allergenen 6nr'!$A$1:$O$1310,11,FALSE) -> + | BM19: =VLOOKUP($A19,'[3]allergenen 6nr'!$A$1:$O$1310,12,FALSE) -> - | BN19: =VLOOKUP($A19,'[3]allergenen 6nr'!$A$1:$O$1310,13,FALSE) -> X | BO19: =VLOOKUP($A19,'[3]allergenen 6nr'!$A$1:$O$1310,14,FALSE) -> - | BP19: =VLOOKUP($A19,'[3]allergenen 6nr'!$A$1:$O$1310,15,FALSE) -> -
A20: 61672000 | B20: =VLOOKUP($A20,[1]maaltijden!$A$1:$IV$65536,4,FALSE) -> APETITO EW AVV BAMI GORENG KIPSATE 475G | C20: =VLOOKUP($A20,[1]maaltijden!$A$1:$IV$65536,7,FALSE) -> C2227-2X WIT | D20: =VLOOKUP($A20,[1]maaltijden!$A$1:$IV$65536,10,FALSE) -> NVT | E20: =VLOOKUP($A20,[1]maaltijden!$A$1:$IV$65536,13,FALSE) -> C2227X8 | F20: =IF($D20="Bedrukte folie 470x300",1,0) -> 0 | G20: =VLOOKUP($A20,[1]maaltijden!$A$1:$IV$65536,27,FALSE) -> X | H20: =VLOOKUP($A20,[1]maaltijden!$A$1:$IV$65536,21,FALSE) -> 5 | I20: 9 | J20: =VLOOKUP($A20,[1]maaltijden!$A$1:$IV$65536,18,FALSE) -> 3 | K20: =VLOOKUP($A20,[1]maaltijden!$A$1:$IV$65536,17,FALSE) -> 3 | L20: =VLOOKUP($A20,[1]maaltijden!$A$1:$IV$65536,20,FALSE) -> 2200 | M20: 2001 | N20: niet samen met 61672200 | O20: 0 | P20: 0 | Q20: 1 | R20: 0 | S20: 0 | T20: 1 | U20: 1 | V20: 1 | W20: 1 | X20: 1 | Y20: 1 | Z20: 0 | AA20: 0 | AB20: 0 | AC20: 1 | AD20: 1 | AE20: 0 | AF20: 0 | AG20: 1 | AH20: 1 | AI20: 1 | AJ20: 1 | AK20: 0 | AL20: 0 | AM20: 0 | AN20: =IFERROR(INDEX([2]lijnopstellingsfiche!$AP$1:$AP$65536,MATCH(A20,[2]lijnopstellingsfiche!$AQ$1:$AQ$65536,0)),"") -> 1 | AO20: 1 | AP20: 0 | AQ20: 1 | AR20: 0 | AS20: 0 | AT20: 1 | AU20: 0 | AV20: 0 | AW20: 0 | AX20: 0 | AY20: 0 | AZ20: 0 | BA20: 1 | BB20: 0 | BC20: 0
A21: 61672100 | B21: =VLOOKUP($A21,[1]maaltijden!$A$1:$IV$65536,4,FALSE) -> APETITO EW AVV NASI GORENG KIPSATE 475G | C21: =VLOOKUP($A21,[1]maaltijden!$A$1:$IV$65536,7,FALSE) -> C2227-2X WIT | D21: =VLOOKUP($A21,[1]maaltijden!$A$1:$IV$65536,10,FALSE) -> NVT | E21: =VLOOKUP($A21,[1]maaltijden!$A$1:$IV$65536,13,FALSE) -> C2227X8 | F21: =IF($D21="Bedrukte folie 470x300",1,0) -> 0 | G21: =VLOOKUP($A21,[1]maaltijden!$A$1:$IV$65536,27,FALSE) -> X | H21: =VLOOKUP($A21,[1]maaltijden!$A$1:$IV$65536,21,FALSE) -> 5 | I21: =VLOOKUP($A21,[1]maaltijden!$A$1:$IV$65536,21,FALSE) -> 5 | J21: =VLOOKUP($A21,[1]maaltijden!$A$1:$IV$65536,18,FALSE) -> 3 | K21: =VLOOKUP($A21,[1]maaltijden!$A$1:$IV$65536,17,FALSE) -> 3 | L21: x | M21: =VLOOKUP($A21,[1]maaltijden!$A$1:$IV$65536,22,FALSE) -> 2200 | O21: 0 | P21: 0 | Q21: 1 | R21: 0 | S21: 0 | T21: 1 | U21: 1 | V21: 1 | W21: 1 | X21: 1 | Y21: 1 | Z21: 0 | AA21: 0 | AB21: 0 | AC21: 1 | AD21: 1 | AE21: 0 | AF21: 0 | AG21: 1 | AH21: 1 | AI21: 1 | AJ21: 1 | AK21: 0 | AL21: 0 | AM21: 0 | AN21: =IFERROR(INDEX([2]lijnopstellingsfiche!$AP$1:$AP$65536,MATCH(A21,[2]lijnopstellingsfiche!$AQ$1:$AQ$65536,0)),"") -> 1 | AO21: 1 | AP21: 0 | AQ21: 1 | AR21: 0 | AS21: 0 | AT21: 1 | AU21: 0 | AV21: 0 | AW21: 0 | AX21: 0 | AY21: 0 | AZ21: 0 | BA21: 1 | BB21: 0 | BC21: 0 | BD21: =VLOOKUP($A21,'[3]allergenen 6nr'!$A$1:$O$1310,3,FALSE) -> + | BE21: =VLOOKUP($A21,'[3]allergenen 6nr'!$A$1:$O$1310,4,FALSE) -> + | BF21: =VLOOKUP($A21,'[3]allergenen 6nr'!$A$1:$O$1310,5,FALSE) -> + | BG21: =VLOOKUP($A21,'[3]allergenen 6nr'!$A$1:$O$1310,6,FALSE) -> - | BH21: =VLOOKUP($A21,'[3]allergenen 6nr'!$A$1:$O$1310,7,FALSE) -> - | BI21: =VLOOKUP($A21,'[3]allergenen 6nr'!$A$1:$O$1310,8,FALSE) -> - | BJ21: =VLOOKUP($A21,'[3]allergenen 6nr'!$A$1:$O$1310,9,FALSE) -> - | BK21: =VLOOKUP($A21,'[3]allergenen 6nr'!$A$1:$O$1310,10,FALSE) -> - | BL21: =VLOOKUP($A21,'[3]allergenen 6nr'!$A$1:$O$1310,11,FALSE) -> + | BM21: =VLOOKUP($A21,'[3]allergenen 6nr'!$A$1:$O$1310,12,FALSE) -> - | BN21: =VLOOKUP($A21,'[3]allergenen 6nr'!$A$1:$O$1310,13,FALSE) -> + | BO21: =VLOOKUP($A21,'[3]allergenen 6nr'!$A$1:$O$1310,14,FALSE) -> - | BP21: =VLOOKUP($A21,'[3]allergenen 6nr'!$A$1:$O$1310,15,FALSE) -> -
A22: 61672200 | B22: =VLOOKUP($A22,[1]maaltijden!$A$1:$IV$65536,4,FALSE) -> APETITO EW AVV BAMI GORENG KIPSATE NA ARM 475G | C22: =VLOOKUP($A22,[1]maaltijden!$A$1:$IV$65536,7,FALSE) -> C2227-2X WIT | D22: =VLOOKUP($A22,[1]maaltijden!$A$1:$IV$65536,10,FALSE) -> NVT | E22: =VLOOKUP($A22,[1]maaltijden!$A$1:$IV$65536,13,FALSE) -> C2227X8 | F22: =IF($D22="Bedrukte folie 470x300",1,0) -> 0 | G22: =VLOOKUP($A22,[1]maaltijden!$A$1:$IV$65536,27,FALSE) -> X | H22: =VLOOKUP($A22,[1]maaltijden!$A$1:$IV$65536,21,FALSE) -> 5 | I22: =VLOOKUP($A22,[1]maaltijden!$A$1:$IV$65536,21,FALSE) -> 5 | J22: =VLOOKUP($A22,[1]maaltijden!$A$1:$IV$65536,18,FALSE) -> 3 | K22: =VLOOKUP($A22,[1]maaltijden!$A$1:$IV$65536,17,FALSE) -> 3 | L22: x | M22: =VLOOKUP($A22,[1]maaltijden!$A$1:$IV$65536,22,FALSE) -> 2200 | O22: 0 | P22: 0 | Q22: 1 | R22: 0 | S22: 0 | T22: 1 | U22: 1 | V22: 1 | W22: 1 | X22: 1 | Y22: 1 | Z22: 0 | AA22: 0 | AB22: 0 | AC22: 1 | AD22: 1 | AE22: 0 | AF22: 0 | AG22: 1 | AH22: 1 | AI22: 1 | AJ22: 1 | AK22: 0 | AL22: 0 | AM22: 0 | AN22: =IFERROR(INDEX([2]lijnopstellingsfiche!$AP$1:$AP$65536,MATCH(A22,[2]lijnopstellingsfiche!$AQ$1:$AQ$65536,0)),"") -> 1 | AO22: 1 | AP22: 0 | AQ22: 1 | AR22: 0 | AS22: 0 | AT22: 1 | AU22: 0 | AV22: 0 | AW22: 0 | AX22: 0 | AY22: 0 | AZ22: 0 | BA22: 1 | BB22: 0 | BC22: 0 | BD22: =VLOOKUP($A22,'[3]allergenen 6nr'!$A$1:$O$1310,3,FALSE) -> + | BE22: =VLOOKUP($A22,'[3]allergenen 6nr'!$A$1:$O$1310,4,FALSE) -> + | BF22: =VLOOKUP($A22,'[3]allergenen 6nr'!$A$1:$O$1310,5,FALSE) -> + | BG22: =VLOOKUP($A22,'[3]allergenen 6nr'!$A$1:$O$1310,6,FALSE) -> X | BH22: =VLOOKUP($A22,'[3]allergenen 6nr'!$A$1:$O$1310,7,FALSE) -> - | BI22: =VLOOKUP($A22,'[3]allergenen 6nr'!$A$1:$O$1310,8,FALSE) -> X | BJ22: =VLOOKUP($A22,'[3]allergenen 6nr'!$A$1:$O$1310,9,FALSE) -> - | BK22: =VLOOKUP($A22,'[3]allergenen 6nr'!$A$1:$O$1310,10,FALSE) -> - | BL22: =VLOOKUP($A22,'[3]allergenen 6nr'!$A$1:$O$1310,11,FALSE) -> - | BM22: =VLOOKUP($A22,'[3]allergenen 6nr'!$A$1:$O$1310,12,FALSE) -> - | BN22: =VLOOKUP($A22,'[3]allergenen 6nr'!$A$1:$O$1310,13,FALSE) -> X | BO22: =VLOOKUP($A22,'[3]allergenen 6nr'!$A$1:$O$1310,14,FALSE) -> - | BP22: =VLOOKUP($A22,'[3]allergenen 6nr'!$A$1:$O$1310,15,FALSE) -> -
A23: 61672300 | B23: =VLOOKUP($A23,[1]maaltijden!$A$1:$IV$65536,4,FALSE) -> APETITO LASAGNE BOLOGNAISE 570G | C23: =VLOOKUP($A23,[1]maaltijden!$A$1:$IV$65536,7,FALSE) -> C2227-1E | D23: =VLOOKUP($A23,[1]maaltijden!$A$1:$IV$65536,10,FALSE) -> NVT | E23: =VLOOKUP($A23,[1]maaltijden!$A$1:$IV$65536,13,FALSE) -> C2227X8 | F23: =IF($D23="Bedrukte folie 470x300",1,0) -> 0 | G23: =VLOOKUP($A23,[1]maaltijden!$A$1:$IV$65536,27,FALSE) -> ! ! ! | H23: =VLOOKUP($A23,[1]maaltijden!$A$1:$IV$65536,21,FALSE) -> 4 | I23: =VLOOKUP($A23,[1]maaltijden!$A$1:$IV$65536,21,FALSE) -> 4 | J23: =VLOOKUP($A23,[1]maaltijden!$A$1:$IV$65536,18,FALSE) -> 3 | K23: =VLOOKUP($A23,[1]maaltijden!$A$1:$IV$65536,17,FALSE) -> 2 | L23: x | M23: =VLOOKUP($A23,[1]maaltijden!$A$1:$IV$65536,22,FALSE) -> 2200 | O23: 0 | P23: 0 | Q23: 1 | R23: 0 | S23: 0 | T23: 1 | U23: 0 | V23: 1 | W23: 1 | X23: 1 | Y23: 1 | Z23: 0 | AA23: 0 | AB23: 1 | AC23: 0 | AD23: 0 | AE23: 0 | AF23: 0 | AG23: 0 | AH23: 2 | AI23: 0 | AJ23: 0 | AK23: 0 | AL23: 0 | AM23: 0 | AN23: =IFERROR(INDEX([2]lijnopstellingsfiche!$AP$1:$AP$65536,MATCH(A23,[2]lijnopstellingsfiche!$AQ$1:$AQ$65536,0)),"") -> - | AO23: 0 | AP23: 1 | AQ23: 4 | AR23: 0 | AS23: 0 | AT23: 0 | AU23: 0 | AV23: 0 | AW23: 0 | AX23: 0 | AY23: 0 | AZ23: 0 | BA23: 1 | BB23: 0 | BC23: 0 | BD23: =VLOOKUP($A23,'[3]allergenen 6nr'!$A$1:$O$1310,3,FALSE) -> - | BE23: =VLOOKUP($A23,'[3]allergenen 6nr'!$A$1:$O$1310,4,FALSE) -> + | BF23: =VLOOKUP($A23,'[3]allergenen 6nr'!$A$1:$O$1310,5,FALSE) -> + | BG23: =VLOOKUP($A23,'[3]allergenen 6nr'!$A$1:$O$1310,6,FALSE) -> - | BH23: =VLOOKUP($A23,'[3]allergenen 6nr'!$A$1:$O$1310,7,FALSE) -> + | BI23: =VLOOKUP($A23,'[3]allergenen 6nr'!$A$1:$O$1310,8,FALSE) -> - | BJ23: =VLOOKUP($A23,'[3]allergenen 6nr'!$A$1:$O$1310,9,FALSE) -> - | BK23: =VLOOKUP($A23,'[3]allergenen 6nr'!$A$1:$O$1310,10,FALSE) -> X | BL23: =VLOOKUP($A23,'[3]allergenen 6nr'!$A$1:$O$1310,11,FALSE) -> + | BM23: =VLOOKUP($A23,'[3]allergenen 6nr'!$A$1:$O$1310,12,FALSE) -> - | BN23: =VLOOKUP($A23,'[3]allergenen 6nr'!$A$1:$O$1310,13,FALSE) -> X | BO23: =VLOOKUP($A23,'[3]allergenen 6nr'!$A$1:$O$1310,14,FALSE) -> X | BP23: =VLOOKUP($A23,'[3]allergenen 6nr'!$A$1:$O$1310,15,FALSE) -> -
A24: 61686000 | B24: =VLOOKUP($A24,[1]maaltijden!$A$1:$IV$65536,4,FALSE) -> LIDL BE AARDAPPELGRATIN XXL 800G | C24: =VLOOKUP($A24,[1]maaltijden!$A$1:$IV$65536,7,FALSE) -> C2227-1E | D24: =VLOOKUP($A24,[1]maaltijden!$A$1:$IV$65536,10,FALSE) -> H10 | E24: =VLOOKUP($A24,[1]maaltijden!$A$1:$IV$65536,13,FALSE) -> H10X8 | F24: =IF($D24="Bedrukte folie 470x300",1,0) -> 0 | G24: =VLOOKUP($A24,[1]maaltijden!$A$1:$IV$65536,27,FALSE) -> ! ! | H24: =VLOOKUP($A24,[1]maaltijden!$A$1:$IV$65536,21,FALSE) -> 3 | I24: =VLOOKUP($A24,[1]maaltijden!$A$1:$IV$65536,21,FALSE) -> 3 | J24: =VLOOKUP($A24,[1]maaltijden!$A$1:$IV$65536,18,FALSE) -> 2 | K24: =VLOOKUP($A24,[1]maaltijden!$A$1:$IV$65536,17,FALSE) -> 1 | L24: =VLOOKUP($A24,[1]maaltijden!$A$1:$IV$65536,20,FALSE) -> 1750 | M24: =VLOOKUP($A24,[1]maaltijden!$A$1:$IV$65536,22,FALSE) -> 1750 | N24: 0 | O24: 0 | P24: 1 | Q24: 2 | R24: 0 | S24: 1 | T24: 1 | U24: 1 | V24: 1 | W24: 1 | X24: 1 | Y24: 1 | Z24: 0 | AA24: 0 | AB24: 0 | AC24: 0 | AD24: 0 | AE24: 1 | AF24: 0 | AG24: 0 | AH24: 2 | AI24: 0 | AJ24: 0 | AK24: 0 | AL24: 0 | AM24: 0 | AN24: =IFERROR(INDEX([2]lijnopstellingsfiche!$AP$1:$AP$65536,MATCH(A24,[2]lijnopstellingsfiche!$AQ$1:$AQ$65536,0)),"") -> 1 | AO24: 0 | AP24: 1 | AQ24: 2 | AR24: 0 | AS24: 1 | AT24: 0 | AU24: 0 | AV24: 0 | AW24: 1 | AX24: 0 | AY24: 1 | AZ24: 1 | BA24: 0 | BB24: 1 | BC24: 0 | BD24: =VLOOKUP($A24,'[3]allergenen 6nr'!$A$1:$O$1310,3,FALSE) -> - | BE24: =VLOOKUP($A24,'[3]allergenen 6nr'!$A$1:$O$1310,4,FALSE) -> - | BF24: =VLOOKUP($A24,'[3]allergenen 6nr'!$A$1:$O$1310,5,FALSE) -> + | BG24: =VLOOKUP($A24,'[3]allergenen 6nr'!$A$1:$O$1310,6,FALSE) -> X | BH24: =VLOOKUP($A24,'[3]allergenen 6nr'!$A$1:$O$1310,7,FALSE) -> + | BI24: =VLOOKUP($A24,'[3]allergenen 6nr'!$A$1:$O$1310,8,FALSE) -> X | BJ24: =VLOOKUP($A24,'[3]allergenen 6nr'!$A$1:$O$1310,9,FALSE) -> - | BK24: =VLOOKUP($A24,'[3]allergenen 6nr'!$A$1:$O$1310,10,FALSE) -> - | BL24: =VLOOKUP($A24,'[3]allergenen 6nr'!$A$1:$O$1310,11,FALSE) -> - | BM24: =VLOOKUP($A24,'[3]allergenen 6nr'!$A$1:$O$1310,12,FALSE) -> - | BN24: =VLOOKUP($A24,'[3]allergenen 6nr'!$A$1:$O$1310,13,FALSE) -> X | BO24: =VLOOKUP($A24,'[3]allergenen 6nr'!$A$1:$O$1310,14,FALSE) -> - | BP24: =VLOOKUP($A24,'[3]allergenen 6nr'!$A$1:$O$1310,15,FALSE) -> -
A25: 61690500 | B25: =VLOOKUP($A25,[1]maaltijden!$A$1:$IV$65536,4,FALSE) -> BOF BE RUNDSTONG MADEIRASAUS MET PUREE 450G | C25: =VLOOKUP($A25,[1]maaltijden!$A$1:$IV$65536,7,FALSE) -> C2227-2X | D25: =VLOOKUP($A25,[1]maaltijden!$A$1:$IV$65536,10,FALSE) -> H10 | E25: =VLOOKUP($A25,[1]maaltijden!$A$1:$IV$65536,13,FALSE) -> H10X8 | F25: =IF($D25="Bedrukte folie 470x300",1,0) -> 0 | G25: =VLOOKUP($A25,[1]maaltijden!$A$1:$IV$65536,27,FALSE) -> ! ! ! | H25: =VLOOKUP($A25,[1]maaltijden!$A$1:$IV$65536,21,FALSE) -> 7 | I25: =VLOOKUP($A25,[1]maaltijden!$A$1:$IV$65536,21,FALSE) -> 7 | J25: =VLOOKUP($A25,[1]maaltijden!$A$1:$IV$65536,18,FALSE) -> 2 | K25: =VLOOKUP($A25,[1]maaltijden!$A$1:$IV$65536,17,FALSE) -> 2 | L25: =VLOOKUP($A25,[1]maaltijden!$A$1:$IV$65536,20,FALSE) -> 2200 | M25: =VLOOKUP($A25,[1]maaltijden!$A$1:$IV$65536,22,FALSE) -> 2200 | N25: 0 | O25: 0 | P25: 1 | Q25: 2 | R25: 0 | S25: 1 | T25: 1 | U25: 0 | V25: 1 | W25: 1 | X25: 1 | Y25: 1 | Z25: 0 | AA25: 1 | AB25: 0 | AC25: 0 | AD25: 0 | AE25: 1 | AF25: 0 | AG25: 0 | AH25: 2 | AI25: 0 | AJ25: 0 | AK25: 0 | AL25: 0 | AM25: 0 | AN25: =IFERROR(INDEX([2]lijnopstellingsfiche!$AP$1:$AP$65536,MATCH(A25,[2]lijnopstellingsfiche!$AQ$1:$AQ$65536,0)),"") -> 5 | AO25: 0 | AP25: 0 | AQ25: 2 | AR25: 1 | AS25: 0 | AT25: 0 | AU25: 0 | AV25: 0 | AW25: 1 | AX25: 0 | AY25: 1 | AZ25: 1 | BA25: 0 | BB25: 1 | BC25: 0 | BD25: =VLOOKUP($A25,'[3]allergenen 6nr'!$A$1:$O$1310,3,FALSE) -> - | BE25: =VLOOKUP($A25,'[3]allergenen 6nr'!$A$1:$O$1310,4,FALSE) -> + | BF25: =VLOOKUP($A25,'[3]allergenen 6nr'!$A$1:$O$1310,5,FALSE) -> + | BG25: =VLOOKUP($A25,'[3]allergenen 6nr'!$A$1:$O$1310,6,FALSE) -> X | BH25: =VLOOKUP($A25,'[3]allergenen 6nr'!$A$1:$O$1310,7,FALSE) -> + | BI25: =VLOOKUP($A25,'[3]allergenen 6nr'!$A$1:$O$1310,8,FALSE) -> X | BJ25: =VLOOKUP($A25,'[3]allergenen 6nr'!$A$1:$O$1310,9,FALSE) -> - | BK25: =VLOOKUP($A25,'[3]allergenen 6nr'!$A$1:$O$1310,10,FALSE) -> - | BL25: =VLOOKUP($A25,'[3]allergenen 6nr'!$A$1:$O$1310,11,FALSE) -> + | BM25: =VLOOKUP($A25,'[3]allergenen 6nr'!$A$1:$O$1310,12,FALSE) -> - | BN25: =VLOOKUP($A25,'[3]allergenen 6nr'!$A$1:$O$1310,13,FALSE) -> X | BO25: =VLOOKUP($A25,'[3]allergenen 6nr'!$A$1:$O$1310,14,FALSE) -> - | BP25: =VLOOKUP($A25,'[3]allergenen 6nr'!$A$1:$O$1310,15,FALSE) -> -
A26: 61691400 | B26: =VLOOKUP($A26,[1]maaltijden!$A$1:$IV$65536,4,FALSE) -> BOF BE HAMBURGER AJUINSAUS VIERGROENTENSTAMPPOT 500G | C26: =VLOOKUP($A26,[1]maaltijden!$A$1:$IV$65536,7,FALSE) -> C2227-2X | D26: =VLOOKUP($A26,[1]maaltijden!$A$1:$IV$65536,10,FALSE) -> H10 | E26: =VLOOKUP($A26,[1]maaltijden!$A$1:$IV$65536,13,FALSE) -> H10X8 | F26: =IF($D26="Bedrukte folie 470x300",1,0) -> 0 | G26: =VLOOKUP($A26,[1]maaltijden!$A$1:$IV$65536,27,FALSE) -> ! ! | H26: =VLOOKUP($A26,[1]maaltijden!$A$1:$IV$65536,21,FALSE) -> 3 | I26: =VLOOKUP($A26,[1]maaltijden!$A$1:$IV$65536,21,FALSE) -> 3 | J26: =VLOOKUP($A26,[1]maaltijden!$A$1:$IV$65536,18,FALSE) -> 2 | K26: =VLOOKUP($A26,[1]maaltijden!$A$1:$IV$65536,17,FALSE) -> 2.5 | L26: =VLOOKUP($A26,[1]maaltijden!$A$1:$IV$65536,20,FALSE) -> 2000 | M26: =VLOOKUP($A26,[1]maaltijden!$A$1:$IV$65536,22,FALSE) -> 2000 | N26: 0 | O26: 0 | P26: 1 | Q26: 2 | R26: 0 | S26: 1 | T26: 1 | U26: 0 | V26: 1 | W26: 1 | X26: 1 | Y26: 1 | Z26: 0 | AA26: 0 | AB26: 0 | AC26: 0 | AD26: 0 | AE26: 1 | AF26: 0 | AG26: 0 | AH26: 2 | AI26: 1 | AJ26: 0 | AK26: 0 | AL26: 0 | AM26: 0 | AN26: =IFERROR(INDEX([2]lijnopstellingsfiche!$AP$1:$AP$65536,MATCH(A26,[2]lijnopstellingsfiche!$AQ$1:$AQ$65536,0)),"") -> - | AO26: 0 | AP26: 0 | AQ26: 1 | AR26: 1 | AS26: 0 | AT26: 0 | AU26: 0 | AV26: 0 | AW26: 1 | AX26: 0 | AY26: 1 | AZ26: 1 | BA26: 0 | BB26: 1 | BC26: 0 | BD26: =VLOOKUP($A26,'[3]allergenen 6nr'!$A$1:$O$1310,3,FALSE) -> - | BE26: =VLOOKUP($A26,'[3]allergenen 6nr'!$A$1:$O$1310,4,FALSE) -> X | BF26: =VLOOKUP($A26,'[3]allergenen 6nr'!$A$1:$O$1310,5,FALSE) -> + | BG26: =VLOOKUP($A26,'[3]allergenen 6nr'!$A$1:$O$1310,6,FALSE) -> X | BH26: =VLOOKUP($A26,'[3]allergenen 6nr'!$A$1:$O$1310,7,FALSE) -> + | BI26: =VLOOKUP($A26,'[3]allergenen 6nr'!$A$1:$O$1310,8,FALSE) -> X | BJ26: =VLOOKUP($A26,'[3]allergenen 6nr'!$A$1:$O$1310,9,FALSE) -> - | BK26: =VLOOKUP($A26,'[3]allergenen 6nr'!$A$1:$O$1310,10,FALSE) -> - | BL26: =VLOOKUP($A26,'[3]allergenen 6nr'!$A$1:$O$1310,11,FALSE) -> X | BM26: =VLOOKUP($A26,'[3]allergenen 6nr'!$A$1:$O$1310,12,FALSE) -> - | BN26: =VLOOKUP($A26,'[3]allergenen 6nr'!$A$1:$O$1310,13,FALSE) -> X | BO26: =VLOOKUP($A26,'[3]allergenen 6nr'!$A$1:$O$1310,14,FALSE) -> - | BP26: =VLOOKUP($A26,'[3]allergenen 6nr'!$A$1:$O$1310,15,FALSE) -> -
A27: 61691500 | B27: =VLOOKUP($A27,[1]maaltijden!$A$1:$IV$65536,4,FALSE) -> BOF BE HAMWITLOOFROLLETJE IN KAASSAUS 800G | C27: =VLOOKUP($A27,[1]maaltijden!$A$1:$IV$65536,7,FALSE) -> C2227-1E | D27: =VLOOKUP($A27,[1]maaltijden!$A$1:$IV$65536,10,FALSE) -> H10 | E27: =VLOOKUP($A27,[1]maaltijden!$A$1:$IV$65536,13,FALSE) -> H10X8 | F27: =IF($D27="Bedrukte folie 470x300",1,0) -> 0 | G27: =VLOOKUP($A27,[1]maaltijden!$A$1:$IV$65536,27,FALSE) -> ! ! | H27: =VLOOKUP($A27,[1]maaltijden!$A$1:$IV$65536,21,FALSE) -> 12 | I27: =VLOOKUP($A27,[1]maaltijden!$A$1:$IV$65536,21,FALSE) -> 12 | J27: =VLOOKUP($A27,[1]maaltijden!$A$1:$IV$65536,18,FALSE) -> 2 | K27: =VLOOKUP($A27,[1]maaltijden!$A$1:$IV$65536,17,FALSE) -> 2 | L27: =VLOOKUP($A27,[1]maaltijden!$A$1:$IV$65536,20,FALSE) -> 950 | M27: =VLOOKUP($A27,[1]maaltijden!$A$1:$IV$65536,22,FALSE) -> 950 | N27: 0 | O27: 0 | P27: 1 | Q27: 2 | R27: 0 | S27: 1 | T27: 1 | U27: 0 | V27: 1 | W27: 1 | X27: 1 | Y27: 1 | Z27: 1 | AA27: 0 | AB27: 0 | AC27: 1 | AD27: 0 | AE27: 1 | AF27: 0 | AG27: 0 | AH27: 1 | AI27: 0 | AJ27: 0 | AK27: 0 | AL27: 0 | AM27: 0 | AN27: =IFERROR(INDEX([2]lijnopstellingsfiche!$AP$1:$AP$65536,MATCH(A27,[2]lijnopstellingsfiche!$AQ$1:$AQ$65536,0)),"") -> 10 | AO27: 0 | AP27: 1 | AQ27: 1 | AR27: 0 | AS27: 0 | AT27: 0 | AU27: 0 | AV27: 0 | AW27: 1 | AX27: 0 | AY27: 1 | AZ27: 1 | BA27: 0 | BB27: 1 | BC27: 0 | BD27: =VLOOKUP($A27,'[3]allergenen 6nr'!$A$1:$O$1310,3,FALSE) -> - | BE27: =VLOOKUP($A27,'[3]allergenen 6nr'!$A$1:$O$1310,4,FALSE) -> - | BF27: =VLOOKUP($A27,'[3]allergenen 6nr'!$A$1:$O$1310,5,FALSE) -> + | BG27: =VLOOKUP($A27,'[3]allergenen 6nr'!$A$1:$O$1310,6,FALSE) -> X | BH27: =VLOOKUP($A27,'[3]allergenen 6nr'!$A$1:$O$1310,7,FALSE) -> + | BI27: =VLOOKUP($A27,'[3]allergenen 6nr'!$A$1:$O$1310,8,FALSE) -> X | BJ27: =VLOOKUP($A27,'[3]allergenen 6nr'!$A$1:$O$1310,9,FALSE) -> - | BK27: =VLOOKUP($A27,'[3]allergenen 6nr'!$A$1:$O$1310,10,FALSE) -> - | BL27: =VLOOKUP($A27,'[3]allergenen 6nr'!$A$1:$O$1310,11,FALSE) -> - | BM27: =VLOOKUP($A27,'[3]allergenen 6nr'!$A$1:$O$1310,12,FALSE) -> - | BN27: =VLOOKUP($A27,'[3]allergenen 6nr'!$A$1:$O$1310,13,FALSE) -> X | BO27: =VLOOKUP($A27,'[3]allergenen 6nr'!$A$1:$O$1310,14,FALSE) -> - | BP27: =VLOOKUP($A27,'[3]allergenen 6nr'!$A$1:$O$1310,15,FALSE) -> -
